Workbook

Sheet 1
E3: PRO MUNDO COMEX S.A.C.
E4: RUC: 20612452432
E7: COTIZACION N002
B8: NOMBRE: | C8: MARIBEL VILMA GONZALES HUANCA | E8: SERVICIO: | F8: CARGA CONSOLIDADA | I8: N° CAJAS: | J8: =+'2'!F7 -> 0
B9: APELLIDO: | E9: FECHA: | F9: =+TODAY() -> 0 | I9: PESO: | J9: 100 Kg
B10: DNI/RUC: | C10: 41877382 | E10: ORIGEN: | F10: CHINA | I10: MEDIDA:
B11: TELEFONO: | C11: 51 940 469 505 | E11: CLIENTE: | F11: NUEVO | I11: CBM | J11: ='2'!K7 -> 0
B13: CALCULO DE BASE IMPONIBLE | K13: MONTO | L13: MONEDA
B14: VALOR DE CARGA | K14: ='2'!K11 -> 0 | L14: USD
B15: FLETE INTERNACIONAL + SEGURO | K15: ='2'!K14 + '2'!K17 -> 0 | L15: USD
B16: VALOR CIF | K16: =SUM(K14:K15) -> 0 | L16: USD
B19: CALCULO DE TRIBUTOS | J19: % | K19: MONTO | L19: MONEDA
B20: ADVALOREM | J20: =MAX('2'!C27:J27) -> 0 | K20: ='2'!K28 -> 0 | L20: USD | N20: Hola MARIBEL VILMA GONZALES HUANCA 😁 un gusto saludarte! A continuación te envío la cotización final de tu importación📋📦. 🙋‍♂️ PAGO PENDIENTE : ☑️Costo CBM: $332.64 ☑️Impuestos: $936.83 ☑️ Total: $1269.47 Pronto le aviso nuevos avances, que tengan buen día🚢 Último día de pago:
B21: IGV | J21: 0.16 | K21: ='2'!K29 -> 0 | L21: USD
B22: IPM | J22: 0.02 | K22: ='2'!K30 -> 0 | L22: USD
B23: SUB TOTAL | K23: =SUM(K20:K22) -> 0 | L23: USD
B25: PERCEPCIÓN | J25: 3.5% | K25: ='2'!K31 -> 0 | L25: USD
B26: TOTAL | K26: =K23+K25 -> 0 | L26: USD
B28: RESUMEN DE COTIZACIÓN | K28: MONTO | L28: MONEDA
B29: VALOR DE CARGA (PAGO AL PROVEEDOR) | K29: =K14 -> 0 | L29: USD
B30: SERVICIO DE IMPORTACIÓN (ORIGEN -FLETE - DESTINO) | K30: =IF(J11<1, '2'!O7, '2'!O7*J11) -> 0 | L30: USD
B31: IMPUESTOS | K31: =K26 -> 0 | L31: USD
B32: MONTO TOTAL | K32: =SUM(K29:K31) -> 0 | L32: USD
B34: SIMULACIÓN DEL PRECIO PUESTO EN PERÚ POR PIEZA
B35: # ITEM | C35: NOMBRE PRODUCTO | F35: CANTIDAD | G35: COSTO UNI. | I35: PRECIO U. | J35: TOTAL | K35: PRECIO UNIT. (SOLES)
B36: 1 | C36: GORRO CON TRENZAS PARA NIÑA | F36: ='2'!C10 -> 0 | G36: ='2'!C8 -> 0 | I36: ='2'!C46 -> 0 | J36: ='2'!C44 -> 0 | K36: ='2'!C47 -> 0
B37: 2 | C37: SOMBRERO MODELO CON OREJITAS | F37: ='2'!D10 -> 0 | G37: ='2'!D8 -> 0 | I37: ='2'!D46 -> 0 | J37: ='2'!D44 -> 0 | K37: ='2'!D47 -> 0
B38: 3 | C38: SOMBRERO VINTAGE PARA NIÑA | F38: ='2'!E10 -> 0 | G38: ='2'!E8 -> 0 | I38: ='2'!E46 -> 0 | J38: ='2'!E44 -> 0 | K38: ='2'!E47 -> 0
B39: 4 | C39: SOMBRERO DE VERANO PARA NIÑAS | F39: ='2'!F10 -> 0 | G39: ='2'!F8 -> 0 | I39: ='2'!F46 -> 0 | J39: ='2'!F44 -> 0 | K39: ='2'!F47 -> 0
B40: 5 | C40: SOMBRERO MODELO GIRASOL | F40: ='2'!G10 -> 0 | G40: ='2'!G8 -> 0 | I40: ='2'!G46 -> 0 | J40: ='2'!G44 -> 0 | K40: ='2'!G47 -> 0
B41: 6 | C41: GORRO MODELO LAZO | F41: ='2'!H10 -> 0 | G41: ='2'!H8 -> 0 | I41: ='2'!H46 -> 0 | J41: ='2'!H44 -> 0 | K41: ='2'!H47 -> 0
B42: 7 | C42: GORRO CON CUELLERA PARA INVIERNO | F42: ='2'!I10 -> 0 | G42: ='2'!I8 -> 0 | I42: ='2'!I46 -> 0 | J42: ='2'!I44 -> 0 | K42: ='2'!I47 -> 0
B43: 8 | C43: GORRO DE INVIERNO MODELO CASTOR | F43: ='2'!J10 -> 0 | G43: ='2'!J8 -> 0 | I43: ='2'!J46 -> 0 | J43: ='2'!J44 -> 0 | K43: ='2'!J47 -> 0
B44: TOTAL | F44: =SUM(F36:F43) -> 0 | J44: =SUM(J36:J43) -> 0
B45: *No se emite comprobante por concepto de "PERCEPCIÓN, ANTI DUMPING, GESTIÓN DE COMPRA"
B46: *A nosotros se nos pagan los Gastos Logísticos + Impuestos una semana antes de que el contenedor
B47: llegue al puerto del Callao.
B48: *El tipo de cambio referencial usado para la conversión a soles es del 3.70
D51: PRO MUNDO COMEX S.A.C.
D52: RUC: 20612452432
...

Sheet 2
B3: Calculo de Tributos
B5: Nombres | C5: GORRO CON TRENZAS PARA NIÑA | D5: SOMBRERO MODELO CON OREJITAS | E5: SOMBRERO VINTAGE PARA NIÑA | F5: SOMBRERO DE VERANO PARA NIÑAS | G5: SOMBRERO MODELO GIRASOL | H5: GORRO MODELO LAZO | I5: GORRO CON CUELLERA PARA INVIERNO | J5: GORRO DE INVIERNO MODELO CASTOR | K5: Total
B6: Peso | C6: 0 | D6: 0 | E6: 0 | F6: 0 | G6: 0 | H6: 0 | I6: 0 | J6: 0 | K6: 100 | N6: Tipo Cliente | O6: Tarifa
B7: Valor CBM | C7: 0 | D7: 0 | E7: 0 | F7: 0 | G7: 0 | H7: 0 | I7: 0 | J7: 0 | K7: 1.55 | N7: NUEVO | O7: 280
B8: Valor Unitario | C8: 1.8 | D8: 1.55 | E8: 2.05 | F8: 1.65 | G8: 2.2 | H8: 1.65 | I8: 1.334375 | J8: 1.54
B9: Valoracion | C9: 0 | D9: 0 | E9: 0 | F9: 0 | G9: 0 | H9: 0 | I9: 0 | J9: 0
B10: Cantidad | C10: 250 | D10: 390 | E10: 199 | F10: 265 | G10: 300 | H10: 275 | I10: 520 | J10: 140 | K10: =SUM(C10:J10) -> 0
B11: Valor FOB | C11: =C8*C10 -> 0 | D11: =D8*D10 -> 0 | E11: =E8*E10 -> 0 | F11: =F8*F10 -> 0 | G11: =G8*G10 -> 0 | H11: =H8*H10 -> 0 | I11: =I8*I10 -> 0 | J11: =J8*J10 -> 0 | K11: =SUM(C11:J11) -> 0
B12: Valor FOB Valoracion | C12: =C10*C9 -> 0 | D12: =D10*D9 -> 0 | E12: =E10*E9 -> 0 | F12: =F10*F9 -> 0 | G12: =G10*G9 -> 0 | H12: =H10*H9 -> 0 | I12: =I10*I9 -> 0 | J12: =J10*J9 -> 0 | K12: =SUM(C12:J12) -> 0
B13: Distribucion % | C13: =C11/K11 -> 0 | D13: =D11/K11 -> 0 | E13: =E11/K11 -> 0 | F13: =F11/K11 -> 0 | G13: =G11/K11 -> 0 | H13: =H11/K11 -> 0 | I13: =I11/K11 -> 0 | J13: =J11/K11 -> 0
B14: Flete | C14: =K14*C13 -> 0 | D14: =K14*D13 -> 0 | E14: =K14*E13 -> 0 | F14: =K14*F13 -> 0 | G14: =K14*G13 -> 0 | H14: =K14*H13 -> 0 | I14: =K14*I13 -> 0 | J14: =K14*J13 -> 0 | K14: =IF(K7<1, O7*0.6, O7*0.6*K7) -> 0
B15: Valor CFR | C15: =C11+C14 -> 0 | D15: =D11+D14 -> 0 | E15: =E11+E14 -> 0 | F15: =F11+F14 -> 0 | G15: =G11+G14 -> 0 | H15: =H11+H14 -> 0 | I15: =I11+I14 -> 0 | J15: =J11+J14 -> 0 | K15: =SUM(C15:J15) -> 0
B16: CFR Valorizado | C16: =C12+C14 -> 0 | D16: =D12+D14 -> 0 | E16: =E12+E14 -> 0 | F16: =F12+F14 -> 0 | G16: =G12+G14 -> 0 | H16: =H12+H14 -> 0 | I16: =I12+I14 -> 0 | J16: =J12+J14 -> 0 | K16: =SUM(C16:J16) -> 0
B17: Seguro | C17: =IF(K11>5000,100*C13,50*C13) -> 0 | D17: =IF(K11>5000,100*D13,50*D13) -> 0 | E17: =IF(K11>5000,100*E13,50*E13) -> 0 | F17: =IF(K11>5000,100*F13,50*F13) -> 0 | G17: =IF(K11>5000,100*G13,50*G13) -> 0 | H17: =IF(K11>5000,100*H13,50*H13) -> 0 | I17: =IF(K11>5000,100*I13,50*I13) -> 0 | J17: =IF(K11>5000,100*J13,50*J13) -> 0 | K17: =SUM(C17:J17) -> 0
B18: Valor CIF | C18: =C15+C17 -> 0 | D18: =D15+D17 -> 0 | E18: =E15+E17 -> 0 | F18: =F15+F17 -> 0 | G18: =G15+G17 -> 0 | H18: =H15+H17 -> 0 | I18: =I15+I17 -> 0 | J18: =J15+J17 -> 0 | K18: =SUM(C18:J18) -> 0
B19: CIF Valorizado | C19: =C16+C17 -> 0 | D19: =D16+D17 -> 0 | E19: =E16+E17 -> 0 | F19: =F16+F17 -> 0 | G19: =G16+G17 -> 0 | H19: =H16+H17 -> 0 | I19: =I16+I17 -> 0 | J19: =J16+J17 -> 0 | K19: =SUM(C19:J19) -> 0
B23: Tributos Aplicables
B26: ANTIDUMPING | C26: 0 | D26: 0 | E26: 0 | F26: 0 | G26: 0 | H26: 0 | I26: 0 | J26: 0 | K26: =SUM(C26:J26) -> 0
C27: 0 | D27: 0 | E27: 0 | F27: 0 | G27: 0 | H27: 0 | I27: 0 | J27: 0 | K27: =SUM(C27:J27) -> 0
B28: AD VALOREM | C28: =MAX(C19,C18)*C27 -> 0 | D28: =MAX(D19,D18)*D27 -> 0 | E28: =MAX(E19,E18)*E27 -> 0 | F28: =MAX(F19,F18)*F27 -> 0 | G28: =MAX(G19,G18)*G27 -> 0 | H28: =MAX(H19,H18)*H27 -> 0 | I28: =MAX(I19,I18)*I27 -> 0 | J28: =MAX(J19,J18)*J27 -> 0 | K28: =SUM(C28:J28) -> 0
B29: IGV | C29: =0.16*(MAX(C19,C18)+C28) -> 0 | D29: =0.16*(MAX(D19,D18)+D28) -> 0 | E29: =0.16*(MAX(E19,E18)+E28) -> 0 | F29: =0.16*(MAX(F19,F18)+F28) -> 0 | G29: =0.16*(MAX(G19,G18)+G28) -> 0 | H29: =0.16*(MAX(H19,H18)+H28) -> 0 | I29: =0.16*(MAX(I19,I18)+I28) -> 0 | J29: =0.16*(MAX(J19,J18)+J28) -> 0 | K29: =SUM(C29:J29) -> 0
B30: IPM | C30: =0.02*(MAX(C19,C18)+C28) -> 0 | D30: =0.02*(MAX(D19,D18)+D28) -> 0 | E30: =0.02*(MAX(E19,E18)+E28) -> 0 | F30: =0.02*(MAX(F19,F18)+F28) -> 0 | G30: =0.02*(MAX(G19,G18)+G28) -> 0 | H30: =0.02*(MAX(H19,H18)+H28) -> 0 | I30: =0.02*(MAX(I19,I18)+I28) -> 0 | J30: =0.02*(MAX(J19,J18)+J28) -> 0 | K30: =SUM(C30:J30) -> 0
B31: PERCEPCION | C31: =0.035*(MAX(C18,C19) +C28+C29+C30) -> 0 | D31: =0.035*(MAX(D18,D19) +D28+D29+D30) -> 0 | E31: =0.035*(MAX(E18,E19) +E28+E29+E30) -> 0 | F31: =0.035*(MAX(F18,F19) +F28+F29+F30) -> 0 | G31: =0.035*(MAX(G18,G19) +G28+G29+G30) -> 0 | H31: =0.035*(MAX(H18,H19) +H28+H29+H30) -> 0 | I31: =0.035*(MAX(I18,I19) +I28+I29+I30) -> 0 | J31: =0.035*(MAX(J18,J19) +J28+J29+J30) -> 0 | K31: =SUM(C31:J31) -> 0
B32: TOTAL | C32: =SUM(C28:C31) -> 0 | D32: =SUM(D28:D31) -> 0 | E32: =SUM(E28:E31) -> 0 | F32: =SUM(F28:F31) -> 0 | G32: =SUM(G28:G31) -> 0 | H32: =SUM(H28:H31) -> 0 | I32: =SUM(I28:I31) -> 0 | J32: =SUM(J28:J31) -> 0 | K32: =SUM(K28:K31) -> 0
B37: Costos Destinos
B40: ITEM | C40: =C13*K40 -> 0 | D40: =D13*K40 -> 0 | E40: =E13*K40 -> 0 | F40: =F13*K40 -> 0 | G40: =G13*K40 -> 0 | H40: =H13*K40 -> 0 | I40: =I13*K40 -> 0 | J40: =J13*K40 -> 0 | K40: =IF(K7<1, O7*0.4,O7*0.4*K7) -> 0
B43: ITEM | C43: GORRO CON TRENZAS PARA NIÑA | D43: SOMBRERO MODELO CON OREJITAS | E43: SOMBRERO VINTAGE PARA NIÑA | F43: SOMBRERO DE VERANO PARA NIÑAS | G43: SOMBRERO MODELO GIRASOL | H43: GORRO MODELO LAZO | I43: GORRO CON CUELLERA PARA INVIERNO | J43: GORRO DE INVIERNO MODELO CASTOR | K43: Total
B44: COSTO TOTAL | C44: =SUM(C15,C40,C32,(C26)) -> 0 | D44: =SUM(D15,D40,D32,(D26)) -> 0 | E44: =SUM(E15,E40,E32,(E26)) -> 0 | F44: =SUM(F15,F40,F32,(F26)) -> 0 | G44: =SUM(G15,G40,G32,(G26)) -> 0 | H44: =SUM(H15,H40,H32,(H26)) -> 0 | I44: =SUM(I15,I40,I32,(I26)) -> 0 | J44: =SUM(J15,J40,J32,(J26)) -> 0 | K44: =SUM(C44:J44) -> 0
B45: CANTIDAD | C45: 250 | D45: 390 | E45: 199 | F45: 265 | G45: 300 | H45: 275 | I45: 520 | J45: 140
B46: COSTO UNITARIO | C46: =SUM(C44/C45) -> 0 | D46: =SUM(D44/D45) -> 0 | E46: =SUM(E44/E45) -> 0 | F46: =SUM(F44/F45) -> 0 | G46: =SUM(G44/G45) -> 0 | H46: =SUM(H44/H45) -> 0 | I46: =SUM(I44/I45) -> 0 | J46: =SUM(J44/J45) -> 0
B47: COSTO SOLES | C47: =C46*3.7 -> 0 | D47: =D46*3.7 -> 0 | E47: =E46*3.7 -> 0 | F47: =F46*3.7 -> 0 | G47: =G46*3.7 -> 0 | H47: =H46*3.7 -> 0 | I47: =I46*3.7 -> 0 | J47: =J46*3.7 -> 0
