Workbook

Sheet 1
E3: PRO MUNDO COMEX S.A.C.
E4: RUC: 20612452432
E7: COTIZACION N002
B8: NOMBRE: | C8: MICHEL LUCANA HUAYTA | E8: SERVICIO: | F8: CARGA CONSOLIDADA | I8: N° CAJAS: | J8: =+'2'!F7 -> 0
B9: APELLIDO: | E9: FECHA: | F9: =+TODAY() -> 0 | I9: PESO: | J9: 0 Kg
B10: DNI/RUC: | E10: ORIGEN: | F10: CHINA | I10: MEDIDA:
B11: TELEFONO: | E11: CLIENTE: | F11: ANTIGUO | I11: CBM | J11: ='2'!J7 -> 0
B13: CALCULO DE BASE IMPONIBLE | K13: MONTO | L13: MONEDA
B14: VALOR DE CARGA | K14: ='2'!J11 -> 0 | L14: USD
B15: FLETE INTERNACIONAL + SEGURO | K15: ='2'!J14 + '2'!J17 -> 0 | L15: USD
B16: VALOR CIF | K16: =SUM(K14:K15) -> 0 | L16: USD
B19: CALCULO DE TRIBUTOS | J19: % | K19: MONTO | L19: MONEDA
B20: ADVALOREM | J20: =MAX('2'!C27:I27) -> 0 | K20: ='2'!J28 -> 0 | L20: USD | N20: Hola MICHEL LUCANA HUAYTA 😁 un gusto saludarte! A continuación te envío la cotización final de tu importación📋📦. 🙋‍♂️ PAGO PENDIENTE : ☑️Costo CBM: $0 ☑️Impuestos: $349.7 ☑️ Total: $349.7 Pronto le aviso nuevos avances, que tengan buen día🚢 Último día de pago:
B21: IGV | J21: 0.16 | K21: ='2'!J29 -> 0 | L21: USD
B22: IPM | J22: 0.02 | K22: ='2'!J30 -> 0 | L22: USD
B23: SUB TOTAL | K23: =SUM(K20:K22) -> 0 | L23: USD
B25: PERCEPCIÓN | J25: 3.5% | K25: ='2'!J31 -> 0 | L25: USD
B26: TOTAL | K26: =K23+K25 -> 0 | L26: USD
B28: RESUMEN DE COTIZACIÓN | K28: MONTO | L28: MONEDA
B29: VALOR DE CARGA (PAGO AL PROVEEDOR) | K29: =K14 -> 0 | L29: USD
B30: SERVICIO DE IMPORTACIÓN (ORIGEN -FLETE - DESTINO) | K30: =IF('2'!N7<1, '2'!N7*J11, '2'!N7*J11) -> 0 | L30: USD
B31: IMPUESTOS | K31: =K26 -> 0 | L31: USD
B32: MONTO TOTAL | K32: =SUM(K29:K31) -> 0 | L32: USD
B34: SIMULACIÓN DEL PRECIO PUESTO EN PERÚ POR PIEZA
B35: # ITEM | C35: NOMBRE PRODUCTO | F35: CANTIDAD | G35: COSTO UNI. | I35: PRECIO U. | J35: TOTAL | K35: PRECIO UNIT. (SOLES)
B36: 1 | C36: TRIPODE CON LUZ LED PARA VIDEO | F36: ='2'!C10 -> 0 | G36: ='2'!C8 -> 0 | I36: ='2'!C46 -> 0 | J36: ='2'!C44 -> 0 | K36: ='2'!C47 -> 0
B37: 2 | C37: BATERÍA PARA LUZ LED DE VIDEO | F37: ='2'!D10 -> 0 | G37: ='2'!D8 -> 0 | I37: ='2'!D46 -> 0 | J37: ='2'!D44 -> 0 | K37: ='2'!D47 -> 0
B38: 3 | C38: LUZ LED PARA FOTOGRAFÍA | F38: ='2'!E10 -> 0 | G38: ='2'!E8 -> 0 | I38: ='2'!E46 -> 0 | J38: ='2'!E44 -> 0 | K38: ='2'!E47 -> 0
B39: 4 | C39: SOFTBOX PARA FOTOGRAFÍA | F39: ='2'!F10 -> 0 | G39: ='2'!F8 -> 0 | I39: ='2'!F46 -> 0 | J39: ='2'!F44 -> 0 | K39: ='2'!F47 -> 0
B40: 5 | C40: SOFTBOX DE MONTAJE PARA FOTOGRAFÍA | F40: ='2'!G10 -> 0 | G40: ='2'!G8 -> 0 | I40: ='2'!G46 -> 0 | J40: ='2'!G44 -> 0 | K40: ='2'!G47 -> 0
B41: 6 | C41: SOFTBOX DE MONTAJE HEXAGONAL | F41: ='2'!H10 -> 0 | G41: ='2'!H8 -> 0 | I41: ='2'!H46 -> 0 | J41: ='2'!H44 -> 0 | K41: ='2'!H47 -> 0
B42: 7 | C42: LUZ LED PARA CELULAR | F42: ='2'!I10 -> 0 | G42: ='2'!I8 -> 0 | I42: ='2'!I46 -> 0 | J42: ='2'!I44 -> 0 | K42: ='2'!I47 -> 0
B43: TOTAL | F43: =SUM(F36:F42) -> 0 | J43: =SUM(J36:J42) -> 0
B44: *No se emite comprobante por concepto de "PERCEPCIÓN, ANTI DUMPING, GESTIÓN DE COMPRA"
B45: *A nosotros se nos pagan los Gastos Logísticos + Impuestos una semana antes de que el contenedor
B46: llegue al puerto del Callao.
B47: *El tipo de cambio referencial usado para la conversión a soles es del 3.70
D50: PRO MUNDO COMEX S.A.C.
D51: RUC: 20612452432
B54: TÉRMINOS Y CONDICIONES:
...

Sheet 2
B3: Calculo de Tributos
B5: Nombres | C5: TRIPODE CON LUZ LED PARA VIDEO | D5: BATERÍA PARA LUZ LED DE VIDEO | E5: LUZ LED PARA FOTOGRAFÍA | F5: SOFTBOX PARA FOTOGRAFÍA | G5: SOFTBOX DE MONTAJE PARA FOTOGRAFÍA | H5: SOFTBOX DE MONTAJE HEXAGONAL | I5: LUZ LED PARA CELULAR | J5: Total
B6: Peso | C6: 0 | D6: 0 | E6: 0 | F6: 0 | G6: 0 | H6: 0 | I6: 0 | J6: 0 | M6: Tipo Cliente | N6: Tarifa
B7: Valor CBM | C7: 0 | D7: 0 | E7: 0 | F7: 0 | G7: 0 | H7: 0 | I7: 0 | M7: ANTIGUO
B8: Valor Unitario | C8: 13.8 | D8: 3.25 | E8: 19.1 | F8: 4.9 | G8: 5.5 | H8: 12.5 | I8: 5
B9: Valoracion | C9: 0 | D9: 0 | E9: 0 | F9: 0 | G9: 0 | H9: 0 | I9: 0
B10: Cantidad | C10: 100 | D10: 20 | E10: 3 | F10: 1 | G10: 1 | H10: 1 | I10: 1 | J10: =SUM(C10:I10) -> 0
B11: Valor FOB | C11: =C8*C10 -> 0 | D11: =D8*D10 -> 0 | E11: =E8*E10 -> 0 | F11: =F8*F10 -> 0 | G11: =G8*G10 -> 0 | H11: =H8*H10 -> 0 | I11: =I8*I10 -> 0 | J11: =SUM(C11:I11) -> 0
B12: Valor FOB Valoracion | C12: =C10*C9 -> 0 | D12: =D10*D9 -> 0 | E12: =E10*E9 -> 0 | F12: =F10*F9 -> 0 | G12: =G10*G9 -> 0 | H12: =H10*H9 -> 0 | I12: =I10*I9 -> 0 | J12: =SUM(C12:I12) -> 0
B13: Distribucion % | C13: =C11/J11 -> 0 | D13: =D11/J11 -> 0 | E13: =E11/J11 -> 0 | F13: =F11/J11 -> 0 | G13: =G11/J11 -> 0 | H13: =H11/J11 -> 0 | I13: =I11/J11 -> 0
B14: Flete | C14: =ROUNDUP(J14*C13,2) -> 0 | D14: =ROUNDUP(J14*D13,2) -> 0 | E14: =ROUNDUP(J14*E13,2) -> 0 | F14: =ROUNDUP(J14*F13,2) -> 0 | G14: =ROUNDUP(J14*G13,2) -> 0 | H14: =ROUNDUP(J14*H13,2) -> 0 | I14: =ROUNDUP(J14*I13,2) -> 0 | J14: =IF(J7<1, ROUNDUP(N7*0.6, 0), ROUNDUP(N7*0.6*J7, 0)) -> 0
B15: Valor CFR | C15: =ROUNDUP(C11+C14,2) -> 0 | D15: =ROUNDUP(D11+D14,2) -> 0 | E15: =ROUNDUP(E11+E14,2) -> 0 | F15: =ROUNDUP(F11+F14,2) -> 0 | G15: =ROUNDUP(G11+G14,2) -> 0 | H15: =ROUNDUP(H11+H14,2) -> 0 | I15: =ROUNDUP(I11+I14,2) -> 0 | J15: =SUM(C15:I15) -> 0
B16: CFR Valorizado | C16: =ROUNDUP(C12+C14,2) -> 0 | D16: =ROUNDUP(D12+D14,2) -> 0 | E16: =ROUNDUP(E12+E14,2) -> 0 | F16: =ROUNDUP(F12+F14,2) -> 0 | G16: =ROUNDUP(G12+G14,2) -> 0 | H16: =ROUNDUP(H12+H14,2) -> 0 | I16: =ROUNDUP(I12+I14,2) -> 0 | J16: =SUM(C16:I16) -> 0
B17: Seguro | C17: =IF(J15>5000,ROUND(100*C13,2),ROUND(50*C13,2)) -> 0 | D17: =IF(J15>5000,ROUND(100*D13,2),ROUND(50*D13,2)) -> 0 | E17: =IF(J15>5000,ROUND(100*E13,2),ROUND(50*E13,2)) -> 0 | F17: =IF(J15>5000,ROUND(100*F13,2),ROUND(50*F13,2)) -> 0 | G17: =IF(J15>5000,ROUND(100*G13,2),ROUND(50*G13,2)) -> 0 | H17: =IF(J15>5000,ROUND(100*H13,2),ROUND(50*H13,2)) -> 0 | I17: =IF(J15>5000,ROUND(100*I13,2),ROUND(50*I13,2)) -> 0 | J17: =SUM(C17:I17) -> 0
B18: Valor CIF | C18: =ROUNDUP(C15+C17,2) -> 0 | D18: =ROUNDUP(D15+D17,2) -> 0 | E18: =ROUNDUP(E15+E17,2) -> 0 | F18: =ROUNDUP(F15+F17,2) -> 0 | G18: =ROUNDUP(G15+G17,2) -> 0 | H18: =ROUNDUP(H15+H17,2) -> 0 | I18: =ROUNDUP(I15+I17,2) -> 0 | J18: =SUM(C18:I18) -> 0
B19: CIF Valorizado | C19: =ROUNDUP(C16+C17,2) -> 0 | D19: =ROUNDUP(D16+D17,2) -> 0 | E19: =ROUNDUP(E16+E17,2) -> 0 | F19: =ROUNDUP(F16+F17,2) -> 0 | G19: =ROUNDUP(G16+G17,2) -> 0 | H19: =ROUNDUP(H16+H17,2) -> 0 | I19: =ROUNDUP(I16+I17,2) -> 0 | J19: =SUM(C19:I19) -> 0
B23: Tributos Aplicables
B26: ANTIDUMPING | C26: 0 | D26: 0 | E26: 0 | F26: 0 | G26: 0 | H26: 0 | I26: 0 | J26: =SUM(C26:I26) -> 0
C27: 0 | D27: 0 | E27: 0 | F27: 0 | G27: 0 | H27: 0 | I27: 0 | J27: =SUM(C27:I27) -> 0
B28: AD VALOREM | C28: =MAX(C19,C18)*C27 -> 0 | D28: =MAX(D19,D18)*D27 -> 0 | E28: =MAX(E19,E18)*E27 -> 0 | F28: =MAX(F19,F18)*F27 -> 0 | G28: =MAX(G19,G18)*G27 -> 0 | H28: =MAX(H19,H18)*H27 -> 0 | I28: =MAX(I19,I18)*I27 -> 0 | J28: =SUM(C28:I28) -> 0
B29: IGV | C29: =0.16*(MAX(C19,C18)+C28) -> 0 | D29: =0.16*(MAX(D19,D18)+D28) -> 0 | E29: =0.16*(MAX(E19,E18)+E28) -> 0 | F29: =0.16*(MAX(F19,F18)+F28) -> 0 | G29: =0.16*(MAX(G19,G18)+G28) -> 0 | H29: =0.16*(MAX(H19,H18)+H28) -> 0 | I29: =0.16*(MAX(I19,I18)+I28) -> 0 | J29: =SUM(C29:I29) -> 0
B30: IPM | C30: =0.02*(MAX(C19,C18)+C28) -> 0 | D30: =0.02*(MAX(D19,D18)+D28) -> 0 | E30: =0.02*(MAX(E19,E18)+E28) -> 0 | F30: =0.02*(MAX(F19,F18)+F28) -> 0 | G30: =0.02*(MAX(G19,G18)+G28) -> 0 | H30: =0.02*(MAX(H19,H18)+H28) -> 0 | I30: =0.02*(MAX(I19,I18)+I28) -> 0 | J30: =SUM(C30:I30) -> 0
B31: PERCEPCION | C31: =0.035*(MAX(C18,C19) +C28+C29+C30) -> 0 | D31: =0.035*(MAX(D18,D19) +D28+D29+D30) -> 0 | E31: =0.035*(MAX(E18,E19) +E28+E29+E30) -> 0 | F31: =0.035*(MAX(F18,F19) +F28+F29+F30) -> 0 | G31: =0.035*(MAX(G18,G19) +G28+G29+G30) -> 0 | H31: =0.035*(MAX(H18,H19) +H28+H29+H30) -> 0 | I31: =0.035*(MAX(I18,I19) +I28+I29+I30) -> 0 | J31: =SUM(C31:I31) -> 0
B32: TOTAL | C32: =SUM(C28:C31) -> 0 | D32: =SUM(D28:D31) -> 0 | E32: =SUM(E28:E31) -> 0 | F32: =SUM(F28:F31) -> 0 | G32: =SUM(G28:G31) -> 0 | H32: =SUM(H28:H31) -> 0 | I32: =SUM(I28:I31) -> 0 | J32: =SUM(J28:J31) -> 0
B37: Costos Destinos
B40: ITEM | C40: =C13*J40 -> 0 | D40: =D13*J40 -> 0 | E40: =E13*J40 -> 0 | F40: =F13*J40 -> 0 | G40: =G13*J40 -> 0 | H40: =H13*J40 -> 0 | I40: =I13*J40 -> 0 | J40: =IF(J7<1, ROUNDUP(N7*0.4, 0), ROUNDUP(N7*0.4*J7, 0)) -> 0
B43: ITEM | C43: TRIPODE CON LUZ LED PARA VIDEO | D43: BATERÍA PARA LUZ LED DE VIDEO | E43: LUZ LED PARA FOTOGRAFÍA | F43: SOFTBOX PARA FOTOGRAFÍA | G43: SOFTBOX DE MONTAJE PARA FOTOGRAFÍA | H43: SOFTBOX DE MONTAJE HEXAGONAL | I43: LUZ LED PARA CELULAR | J43: Total
B44: COSTO TOTAL | C44: =SUM(C15,C40,C32,(C26*C10)) -> 0 | D44: =SUM(D15,D40,D32,(D26*D10)) -> 0 | E44: =SUM(E15,E40,E32,(E26*E10)) -> 0 | F44: =SUM(F15,F40,F32,(F26*F10)) -> 0 | G44: =SUM(G15,G40,G32,(G26*G10)) -> 0 | H44: =SUM(H15,H40,H32,(H26*H10)) -> 0 | I44: =SUM(I15,I40,I32,(I26*I10)) -> 0 | J44: =SUM(C44:I44) -> 0
B45: CANTIDAD | C45: 100 | D45: 20 | E45: 3 | F45: 1 | G45: 1 | H45: 1 | I45: 1
B46: COSTO UNITARIO | C46: =ROUND(SUM(C44/C45),2) -> 0 | D46: =ROUND(SUM(D44/D45),2) -> 0 | E46: =ROUND(SUM(E44/E45),2) -> 0 | F46: =ROUND(SUM(F44/F45),2) -> 0 | G46: =ROUND(SUM(G44/G45),2) -> 0 | H46: =ROUND(SUM(H44/H45),2) -> 0 | I46: =ROUND(SUM(I44/I45),2) -> 0
B47: COSTO SOLES | C47: =ROUND(C46*3.7,2) -> 0 | D47: =ROUND(D46*3.7,2) -> 0 | E47: =ROUND(E46*3.7,2) -> 0 | F47: =ROUND(F46*3.7,2) -> 0 | G47: =ROUND(G46*3.7,2) -> 0 | H47: =ROUND(H46*3.7,2) -> 0 | I47: =ROUND(I46*3.7,2) -> 0
