Workbook

Sheet 1
E3: PRO MUNDO COMEX S.A.C.
E4: RUC: 20612452432
E7: COTIZACION N002
B8: NOMBRE: | C8: CLAUDIA VILLAGOMEZ(YUAN YUAN EXP) | E8: SERVICIO: | F8: CARGA CONSOLIDADA | I8: N° CAJAS: | J8: =+'2'!F7 -> 0
B9: APELLIDO: | E9: FECHA: | F9: =+TODAY() -> 0 | I9: PESO: | J9: 0 Kg
B10: DNI/RUC: | E10: ORIGEN: | F10: CHINA | I10: MEDIDA:
B11: TELEFONO: | E11: CLIENTE: | F11: SOCIO | I11: CBM | J11: ='2'!F7 -> 0
B13: CALCULO DE BASE IMPONIBLE | K13: MONTO | L13: MONEDA
B14: VALOR DE CARGA | K14: ='2'!F11 -> 0 | L14: USD
B15: FLETE INTERNACIONAL + SEGURO | K15: ='2'!F14 + '2'!F17 -> 0 | L15: USD
B16: VALOR CIF | K16: =SUM(K14:K15) -> 0 | L16: USD
B19: CALCULO DE TRIBUTOS | J19: % | K19: MONTO | L19: MONEDA
B20: ADVALOREM | J20: =MAX('2'!C27:E27) -> 0 | K20: ='2'!F28 -> 0 | L20: USD | N20: Hola CLAUDIA VILLAGOMEZ(YUAN YUAN EXP) 😁 un gusto saludarte! A continuación te envío la cotización final de tu importación📋📦. 🙋‍♂️ PAGO PENDIENTE : ☑️Costo CBM: $0 ☑️Impuestos: $227.39 ☑️ Total: $227.39 Pronto le aviso nuevos avances, que tengan buen día🚢 Último día de pago:
B21: IGV | J21: 0.16 | K21: ='2'!F29 -> 0 | L21: USD
B22: IPM | J22: 0.02 | K22: ='2'!F30 -> 0 | L22: USD
B23: SUB TOTAL | K23: =SUM(K20:K22) -> 0 | L23: USD
B25: PERCEPCIÓN | J25: 3.5% | K25: ='2'!F31 -> 0 | L25: USD
B26: TOTAL | K26: =K23+K25 -> 0 | L26: USD
B28: RESUMEN DE COTIZACIÓN | K28: MONTO | L28: MONEDA
B29: VALOR DE CARGA (PAGO AL PROVEEDOR) | K29: =K14 -> 0 | L29: USD
B30: SERVICIO DE IMPORTACIÓN (ORIGEN -FLETE - DESTINO) | K30: =IF('2'!J7<1, '2'!J7*J11, '2'!J7*J11) -> 0 | L30: USD
B31: IMPUESTOS | K31: =K26 -> 0 | L31: USD
B32: MONTO TOTAL | K32: =SUM(K29:K31) -> 0 | L32: USD
B34: SIMULACIÓN DEL PRECIO PUESTO EN PERÚ POR PIEZA
B35: # ITEM | C35: NOMBRE PRODUCTO | F35: CANTIDAD | G35: COSTO UNI. | I35: PRECIO U. | J35: TOTAL | K35: PRECIO UNIT. (SOLES)
B36: 1 | C36: ORGANIZADOR DE CABLES PARA ESCRITORIO | F36: ='2'!C10 -> 0 | G36: ='2'!C8 -> 0 | I36: ='2'!C46 -> 0 | J36: ='2'!C44 -> 0 | K36: ='2'!C47 -> 0
B37: 2 | C37: ALFOMBRILLA PARA MOUSE | F37: ='2'!D10 -> 0 | G37: ='2'!D8 -> 0 | I37: ='2'!D46 -> 0 | J37: ='2'!D44 -> 0 | K37: ='2'!D47 -> 0
B38: 3 | C38: SILLA GIRATORIA PARA OFICINA | F38: ='2'!E10 -> 0 | G38: ='2'!E8 -> 0 | I38: ='2'!E46 -> 0 | J38: ='2'!E44 -> 0 | K38: ='2'!E47 -> 0
B39: TOTAL | F39: =SUM(F36:F38) -> 0 | J39: =SUM(J36:J38) -> 0
B42: NOTAS:
B43: *Las fechas brindadas son estimadas, estan sujetas a variación.
B44: *No se emite comprobante por concepto de "PERCEPCIÓN, ANTI DUMPING, GESTIÓN DE COMPRA"
B45: *A nosotros se nos pagan los Gastos Logísticos + Impuestos una semana antes de que el contenedor
B46: llegue al puerto del Callao.
B47: *El tipo de cambio referencial usado para la conversión a soles es del 3.70
D50: PRO MUNDO COMEX S.A.C.
D51: RUC: 20612452432
B54: TÉRMINOS Y CONDICIONES:
B56: 1. Todos los pagos se realizan en dólares.
B57: 2.Todas las marcas de los productos deben ser verificadas por el cliente,
...

Sheet 2
B3: Calculo de Tributos
B5: Nombres | C5: ORGANIZADOR DE CABLES PARA ESCRITORIO | D5: ALFOMBRILLA PARA MOUSE | E5: SILLA GIRATORIA PARA OFICINA | F5: Total
B6: Peso | C6: 0 | D6: 0 | E6: 0 | F6: 0 | I6: Tipo Cliente | J6: Tarifa
B7: Valor CBM | C7: 0 | D7: 0 | E7: 0 | I7: SOCIO
B8: Valor Unitario | C8: 1.97 | D8: 1.86 | E8: 15
B9: Valoracion | C9: 0 | D9: 0 | E9: 0
B10: Cantidad | C10: 50 | D10: 150 | E10: 40 | F10: =SUM(C10:E10) -> 0
B11: Valor FOB | C11: =C8*C10 -> 0 | D11: =D8*D10 -> 0 | E11: =E8*E10 -> 0 | F11: =SUM(C11:E11) -> 0
B12: Valor FOB Valoracion | C12: =C10*C9 -> 0 | D12: =D10*D9 -> 0 | E12: =E10*E9 -> 0 | F12: =SUM(C12:E12) -> 0
B13: Distribucion % | C13: =C11/F11 -> 0 | D13: =D11/F11 -> 0 | E13: =E11/F11 -> 0
B14: Flete | C14: =ROUNDUP(F14*C13,2) -> 0 | D14: =ROUNDUP(F14*D13,2) -> 0 | E14: =ROUNDUP(F14*E13,2) -> 0 | F14: =IF(F7<1, ROUNDUP(J7*0.6, 0), ROUNDUP(J7*0.6*F7, 0)) -> 0
B15: Valor CFR | C15: =ROUNDUP(C11+C14,2) -> 0 | D15: =ROUNDUP(D11+D14,2) -> 0 | E15: =ROUNDUP(E11+E14,2) -> 0 | F15: =SUM(C15:E15) -> 0
B16: CFR Valorizado | C16: =ROUNDUP(C12+C14,2) -> 0 | D16: =ROUNDUP(D12+D14,2) -> 0 | E16: =ROUNDUP(E12+E14,2) -> 0 | F16: =SUM(C16:E16) -> 0
B17: Seguro | C17: =IF(F15>5000,ROUND(100*C13,2),ROUND(50*C13,2)) -> 0 | D17: =IF(F15>5000,ROUND(100*D13,2),ROUND(50*D13,2)) -> 0 | E17: =IF(F15>5000,ROUND(100*E13,2),ROUND(50*E13,2)) -> 0 | F17: =SUM(C17:E17) -> 0
B18: Valor CIF | C18: =ROUNDUP(C15+C17,2) -> 0 | D18: =ROUNDUP(D15+D17,2) -> 0 | E18: =ROUNDUP(E15+E17,2) -> 0 | F18: =SUM(C18:E18) -> 0
B19: CIF Valorizado | C19: =ROUNDUP(C16+C17,2) -> 0 | D19: =ROUNDUP(D16+D17,2) -> 0 | E19: =ROUNDUP(E16+E17,2) -> 0 | F19: =SUM(C19:E19) -> 0
B23: Tributos Aplicables
B26: ANTIDUMPING | C26: 0 | D26: 0 | E26: 0 | F26: =SUM(C26:E26) -> 0
C27: 0 | D27: 0 | E27: 0 | F27: =SUM(C27:E27) -> 0
B28: AD VALOREM | C28: =MAX(C19,C18)*C27 -> 0 | D28: =MAX(D19,D18)*D27 -> 0 | E28: =MAX(E19,E18)*E27 -> 0 | F28: =SUM(C28:E28) -> 0
B29: IGV | C29: =0.16*(MAX(C19,C18)+C28) -> 0 | D29: =0.16*(MAX(D19,D18)+D28) -> 0 | E29: =0.16*(MAX(E19,E18)+E28) -> 0 | F29: =SUM(C29:E29) -> 0
B30: IPM | C30: =0.02*(MAX(C19,C18)+C28) -> 0 | D30: =0.02*(MAX(D19,D18)+D28) -> 0 | E30: =0.02*(MAX(E19,E18)+E28) -> 0 | F30: =SUM(C30:E30) -> 0
B31: PERCEPCION | C31: =0.035*(MAX(C18,C19) +C28+C29+C30) -> 0 | D31: =0.035*(MAX(D18,D19) +D28+D29+D30) -> 0 | E31: =0.035*(MAX(E18,E19) +E28+E29+E30) -> 0 | F31: =SUM(C31:E31) -> 0
B32: TOTAL | C32: =SUM(C28:C31) -> 0 | D32: =SUM(D28:D31) -> 0 | E32: =SUM(E28:E31) -> 0 | F32: =SUM(F28:F31) -> 0
B37: Costos Destinos
B40: ITEM | C40: =C13*F40 -> 0 | D40: =D13*F40 -> 0 | E40: =E13*F40 -> 0 | F40: =IF(F7<1, ROUNDUP(J7*0.4, 0), ROUNDUP(J7*0.4*F7, 0)) -> 0
B43: ITEM | C43: ORGANIZADOR DE CABLES PARA ESCRITORIO | D43: ALFOMBRILLA PARA MOUSE | E43: SILLA GIRATORIA PARA OFICINA | F43: Total
B44: COSTO TOTAL | C44: =SUM(C15,C40,C32,(C26*C10)) -> 0 | D44: =SUM(D15,D40,D32,(D26*D10)) -> 0 | E44: =SUM(E15,E40,E32,(E26*E10)) -> 0 | F44: =SUM(C44:E44) -> 0
B45: CANTIDAD | C45: 50 | D45: 150 | E45: 40
B46: COSTO UNITARIO | C46: =ROUND(SUM(C44/C45),2) -> 0 | D46: =ROUND(SUM(D44/D45),2) -> 0 | E46: =ROUND(SUM(E44/E45),2) -> 0
B47: COSTO SOLES | C47: =ROUND(C46*3.7,2) -> 0 | D47: =ROUND(D46*3.7,2) -> 0 | E47: =ROUND(E46*3.7,2) -> 0
