Workbook

Sheet 1
E3: PRO MUNDO COMEX S.A.C.
E4: RUC: 20612452432
E7: COTIZACION N002
B8: NOMBRE: | C8: JOSE SMITH | E8: SERVICIO: | F8: CARGA CONSOLIDADA | I8: N° CAJAS: | J8: =+'2'!F7 -> 0
B9: APELLIDO: | E9: FECHA: | F9: =+TODAY() -> 0 | I9: PESO: | J9: 338.4 Kg
B10: DNI/RUC: | C10: 1234567 | E10: ORIGEN: | F10: CHINA | I10: MEDIDA:
B11: TELEFONO: | C11: 51 906 118 935 | E11: CLIENTE: | F11: ANTIGUO | I11: CBM | J11: ='2'!V7 -> 0
B13: CALCULO DE BASE IMPONIBLE | K13: MONTO | L13: MONEDA
B14: VALOR DE CARGA | K14: ='2'!V11 -> 0 | L14: USD
B15: FLETE INTERNACIONAL + SEGURO | K15: ='2'!V14 + '2'!V17 -> 0 | L15: USD
B16: VALOR CIF | K16: =SUM(K14:K15) -> 0 | L16: USD
B19: CALCULO DE TRIBUTOS | J19: % | K19: MONTO | L19: MONEDA
B20: ADVALOREM | J20: =MAX('2'!C27:U27) -> 0 | K20: ='2'!V28 -> 0 | L20: USD | N20: Hola JOSE SMITH 😁 un gusto saludarte! A continuación te envío la cotización final de tu importación📋📦. 🙋‍♂️ PAGO PENDIENTE : ☑️Costo CBM: $0 ☑️Impuestos: $5484.1 ☑️ Total: $5484.1 Pronto le aviso nuevos avances, que tengan buen día🚢 Último día de pago:
B21: IGV | J21: 0.16 | K21: ='2'!V29 -> 0 | L21: USD
B22: IPM | J22: 0.02 | K22: ='2'!V30 -> 0 | L22: USD
B23: SUB TOTAL | K23: =SUM(K20:K22) -> 0 | L23: USD
B25: PERCEPCIÓN | J25: 3.5% | K25: ='2'!V31 -> 0 | L25: USD
B26: TOTAL | K26: =K23+K25 -> 0 | L26: USD
B28: RESUMEN DE COTIZACIÓN | K28: MONTO | L28: MONEDA
B29: VALOR DE CARGA (PAGO AL PROVEEDOR) | K29: =K14 -> 0 | L29: USD
B30: SERVICIO DE IMPORTACIÓN (ORIGEN -FLETE - DESTINO) | K30: =IF('2'!Z7<1, '2'!Z7*J11, '2'!Z7*J11) -> 0 | L30: USD
B31: IMPUESTOS | K31: =K26 -> 0 | L31: USD
B32: MONTO TOTAL | K32: =SUM(K29:K31) -> 0 | L32: USD
B34: SIMULACIÓN DEL PRECIO PUESTO EN PERÚ POR PIEZA
B35: # ITEM | C35: NOMBRE PRODUCTO | F35: CANTIDAD | G35: COSTO UNI. | I35: PRECIO U. | J35: TOTAL | K35: PRECIO UNIT. (SOLES)
B36: 1 | C36: POSA RUEDAS O TOPES PARA RUEDAS | F36: ='2'!C10 -> 0 | G36: ='2'!C8 -> 0 | I36: ='2'!C46 -> 0 | J36: ='2'!C44 -> 0 | K36: ='2'!C47 -> 0
B37: 2 | C37: CARTERAS PARA DAMA | F37: ='2'!D10 -> 0 | G37: ='2'!D8 -> 0 | I37: ='2'!D46 -> 0 | J37: ='2'!D44 -> 0 | K37: ='2'!D47 -> 0
B38: 3 | C38: SCOOTER ELECTRICO PARA NIÑO | F38: ='2'!E10 -> 0 | G38: ='2'!E8 -> 0 | I38: ='2'!E46 -> 0 | J38: ='2'!E44 -> 0 | K38: ='2'!E47 -> 0
B39: 4 | C39: ADAPTADOR USB SATA | F39: ='2'!F10 -> 0 | G39: ='2'!F8 -> 0 | I39: ='2'!F46 -> 0 | J39: ='2'!F44 -> 0 | K39: ='2'!F47 -> 0
B40: 5 | C40: CASE PARA DISCO DURO | F40: ='2'!G10 -> 0 | G40: ='2'!G8 -> 0 | I40: ='2'!G46 -> 0 | J40: ='2'!G44 -> 0 | K40: ='2'!G47 -> 0
B41: 6 | C41: CADDY 2.5" PARA COMPUTADORA | F41: ='2'!H10 -> 0 | G41: ='2'!H8 -> 0 | I41: ='2'!H46 -> 0 | J41: ='2'!H44 -> 0 | K41: ='2'!H47 -> 0
B42: 7 | C42: MOTHERBOARD H61 PARA COMPUTADORA | F42: ='2'!I10 -> 0 | G42: ='2'!I8 -> 0 | I42: ='2'!I46 -> 0 | J42: ='2'!I44 -> 0 | K42: ='2'!I47 -> 0
B43: 8 | C43: MOTHERBOARD H81 PARA COMPUTADORA | F43: ='2'!J10 -> 0 | G43: ='2'!J8 -> 0 | I43: ='2'!J46 -> 0 | J43: ='2'!J44 -> 0 | K43: ='2'!J47 -> 0
B44: 9 | C44: TARJETA GRAFICA GT730 PARA COMPUTADORA | F44: ='2'!K10 -> 0 | G44: ='2'!K8 -> 0 | I44: ='2'!K46 -> 0 | J44: ='2'!K44 -> 0 | K44: ='2'!K47 -> 0
B45: 10 | C45: TARJETA GRAFICA GTX750TI PARA COMPUTADORA | F45: ='2'!L10 -> 0 | G45: ='2'!L8 -> 0 | I45: ='2'!L46 -> 0 | J45: ='2'!L44 -> 0 | K45: ='2'!L47 -> 0
B46: 11 | C46: AFEITADORA ELÉCTRICA CDH002-MN | F46: ='2'!M10 -> 0 | G46: ='2'!M8 -> 0 | I46: ='2'!M46 -> 0 | J46: ='2'!M44 -> 0 | K46: ='2'!M47 -> 0
B47: 12 | C47: CAPA PARA BARBERIA | F47: ='2'!N10 -> 0 | G47: ='2'!N8 -> 0 | I47: ='2'!N46 -> 0 | J47: ='2'!N44 -> 0 | K47: ='2'!N47 -> 0
B48: 13 | C48: AFEITADORA CLASICA AJUSTABLE | F48: ='2'!O10 -> 0 | G48: ='2'!O8 -> 0 | I48: ='2'!O46 -> 0 | J48: ='2'!O44 -> 0 | K48: ='2'!O47 -> 0
B49: 14 | C49: BASE DE SOPORTE PARA MAQUINA DE AFEITAR | F49: ='2'!P10 -> 0 | G49: ='2'!P8 -> 0 | I49: ='2'!P46 -> 0 | J49: ='2'!P44 -> 0 | K49: ='2'!P47 -> 0
B50: 15 | C50: SET DE 50 HOJAS PARA AFEITAR | F50: ='2'!Q10 -> 0 | G50: ='2'!Q8 -> 0 | I50: ='2'!Q46 -> 0 | J50: ='2'!Q44 -> 0 | K50: ='2'!Q47 -> 0
...

Sheet 2
B3: Calculo de Tributos
B5: Nombres | C5: POSA RUEDAS O TOPES PARA RUEDAS | D5: CARTERAS PARA DAMA | E5: SCOOTER ELECTRICO PARA NIÑO | F5: ADAPTADOR USB SATA | G5: CASE PARA DISCO DURO | H5: CADDY 2.5" PARA COMPUTADORA | I5: MOTHERBOARD H61 PARA COMPUTADORA | J5: MOTHERBOARD H81 PARA COMPUTADORA | K5: TARJETA GRAFICA GT730 PARA COMPUTADORA | L5: TARJETA GRAFICA GTX750TI PARA COMPUTADORA | M5: AFEITADORA ELÉCTRICA CDH002-MN | N5: CAPA PARA BARBERIA | O5: AFEITADORA CLASICA AJUSTABLE | P5: BASE DE SOPORTE PARA MAQUINA DE AFEITAR | Q5: SET DE 50 HOJAS PARA AFEITAR | R5: EMBRAGUE DE LIBERACIÓN PARA BATERIA ACUSTICA | S5: ABRAZADERA PARA TABOR DE BATERÍA ACUSTICA | T5: SET DE SEGURO PARA PLATILLOS | U5: TUERCAS PARA PLATILLOS DE BATERIA | V5: Total
B6: Peso | C6: 0 | D6: 0 | E6: 0 | F6: 0 | G6: 0 | H6: 0 | I6: 0 | J6: 0 | K6: 0 | L6: 0 | M6: 0 | N6: 0 | O6: 0 | P6: 0 | Q6: 0 | R6: 0 | S6: 0 | T6: 0 | U6: 0 | V6: 338.4 | Y6: Tipo Cliente | Z6: Tarifa
B7: Valor CBM | C7: 0 | D7: 0 | E7: 0 | F7: 0 | G7: 0 | H7: 0 | I7: 0 | J7: 0 | K7: 0 | L7: 0 | M7: 0 | N7: 0 | O7: 0 | P7: 0 | Q7: 0 | R7: 0 | S7: 0 | T7: 0 | U7: 0 | V7: 18 | Y7: ANTIGUO
B8: Valor Unitario | C8: 0.46 | D8: 5.9 | E8: 40 | F8: 0.5 | G8: 0.6 | H8: 0.3 | I8: 7.2 | J8: 10 | K8: 31.21 | L8: 43.8 | M8: 8 | N8: 1.2 | O8: 3.7555556 | P8: 1.8 | Q8: 1.5 | R8: 3.5 | S8: 13.6 | T8: 3 | U8: 0.4
B9: Valoracion | C9: 0 | D9: 0 | E9: 0 | F9: 0 | G9: 0 | H9: 0 | I9: 0 | J9: 0 | K9: 0 | L9: 0 | M9: 0 | N9: 0 | O9: 0 | P9: 0 | Q9: 0 | R9: 0 | S9: 0 | T9: 0 | U9: 0
B10: Cantidad | C10: 400 | D10: 50 | E10: 10 | F10: 1000 | G10: 2000 | H10: 500 | I10: 500 | J10: 500 | K10: 20 | L10: 21 | M10: 1000 | N10: 1000 | O10: 450 | P10: 50 | Q10: 100 | R10: 20 | S10: 30 | T10: 50 | U10: 100 | V10: =SUM(C10:U10) -> 0
B11: Valor FOB | C11: =C8*C10 -> 0 | D11: =D8*D10 -> 0 | E11: =E8*E10 -> 0 | F11: =F8*F10 -> 0 | G11: =G8*G10 -> 0 | H11: =H8*H10 -> 0 | I11: =I8*I10 -> 0 | J11: =J8*J10 -> 0 | ... U11: =U8*U10 -> 0 | V11: =SUM(C11:U11) -> 0
B12: Valor FOB Valoracion | C12: =C10*C9 -> 0 | D12: =D10*D9 -> 0 | E12: =E10*E9 -> 0 | F12: =F10*F9 -> 0 | G12: =G10*G9 -> 0 | H12: =H10*H9 -> 0 | I12: =I10*I9 -> 0 | J12: =J10*J9 -> 0 | ... U12: =U10*U9 -> 0 | V12: =SUM(C12:U12) -> 0
B13: Distribucion % | C13: =C11/V11 -> 0 | D13: =D11/V11 -> 0 | E13: =E11/V11 -> 0 | F13: =F11/V11 -> 0 | G13: =G11/V11 -> 0 | H13: =H11/V11 -> 0 | I13: =I11/V11 -> 0 | J13: =J11/V11 -> 0 | K13: =K11/V11 -> 0 | L13: =L11/V11 -> 0 | M13: =M11/V11 -> 0 | N13: =N11/V11 -> 0 | O13: =O11/V11 -> 0 | P13: =P11/V11 -> 0 | Q13: =Q11/V11 -> 0 | R13: =R11/V11 -> 0 | S13: =S11/V11 -> 0 | T13: =T11/V11 -> 0 | U13: =U11/V11 -> 0
B14: Flete | C14: =V14*C13 -> 0 | D14: =V14*D13 -> 0 | E14: =V14*E13 -> 0 | F14: =V14*F13 -> 0 | G14: =V14*G13 -> 0 | H14: =V14*H13 -> 0 | I14: =V14*I13 -> 0 | J14: =V14*J13 -> 0 | K14: =V14*K13 -> 0 | L14: =V14*L13 -> 0 | M14: =V14*M13 -> 0 | N14: =V14*N13 -> 0 | O14: =V14*O13 -> 0 | P14: =V14*P13 -> 0 | Q14: =V14*Q13 -> 0 | R14: =V14*R13 -> 0 | S14: =V14*S13 -> 0 | T14: =V14*T13 -> 0 | U14: =V14*U13 -> 0 | V14: =IF(V7<1, Z7*0.6, Z7*0.6*V7) -> 0
B15: Valor CFR | C15: =C11+C14 -> 0 | D15: =D11+D14 -> 0 | E15: =E11+E14 -> 0 | F15: =F11+F14 -> 0 | G15: =G11+G14 -> 0 | H15: =H11+H14 -> 0 | I15: =I11+I14 -> 0 | J15: =J11+J14 -> 0 | ... U15: =U11+U14 -> 0 | V15: =SUM(C15:U15) -> 0
B16: CFR Valorizado | C16: =C12+C14 -> 0 | D16: =D12+D14 -> 0 | E16: =E12+E14 -> 0 | F16: =F12+F14 -> 0 | G16: =G12+G14 -> 0 | H16: =H12+H14 -> 0 | I16: =I12+I14 -> 0 | J16: =J12+J14 -> 0 | ... U16: =U12+U14 -> 0 | V16: =SUM(C16:U16) -> 0
B17: Seguro | C17: =IF(V15>5000,100*C13,50*C13) -> 0 | D17: =IF(V15>5000,100*D13,50*D13) -> 0 | E17: =IF(V15>5000,100*E13,50*E13) -> 0 | F17: =IF(V15>5000,100*F13,50*F13) -> 0 | G17: =IF(V15>5000,100*G13,50*G13) -> 0 | H17: =IF(V15>5000,100*H13,50*H13) -> 0 | I17: =IF(V15>5000,100*I13,50*I13) -> 0 | J17: =IF(V15>5000,100*J13,50*J13) -> 0 | K17: =IF(V15>5000,100*K13,50*K13) -> 0 | L17: =IF(V15>5000,100*L13,50*L13) -> 0 | M17: =IF(V15>5000,100*M13,50*M13) -> 0 | N17: =IF(V15>5000,100*N13,50*N13) -> 0 | O17: =IF(V15>5000,100*O13,50*O13) -> 0 | P17: =IF(V15>5000,100*P13,50*P13) -> 0 | Q17: =IF(V15>5000,100*Q13,50*Q13) -> 0 | R17: =IF(V15>5000,100*R13,50*R13) -> 0 | S17: =IF(V15>5000,100*S13,50*S13) -> 0 | T17: =IF(V15>5000,100*T13,50*T13) -> 0 | U17: =IF(V15>5000,100*U13,50*U13) -> 0 | V17: =SUM(C17:U17) -> 0
B18: Valor CIF | C18: =C15+C17 -> 0 | D18: =D15+D17 -> 0 | E18: =E15+E17 -> 0 | F18: =F15+F17 -> 0 | G18: =G15+G17 -> 0 | H18: =H15+H17 -> 0 | I18: =I15+I17 -> 0 | J18: =J15+J17 -> 0 | ... U18: =U15+U17 -> 0 | V18: =SUM(C18:U18) -> 0
B19: CIF Valorizado | C19: =C16+C17 -> 0 | D19: =D16+D17 -> 0 | E19: =E16+E17 -> 0 | F19: =F16+F17 -> 0 | G19: =G16+G17 -> 0 | H19: =H16+H17 -> 0 | I19: =I16+I17 -> 0 | J19: =J16+J17 -> 0 | ... U19: =U16+U17 -> 0 | V19: =SUM(C19:U19) -> 0
B23: Tributos Aplicables
B26: ANTIDUMPING | C26: 0 | D26: 0 | E26: 0 | F26: 0 | G26: 0 | H26: 0 | I26: 0 | J26: 0 | K26: 0 | L26: 0 | M26: 0 | N26: 0 | O26: 0 | P26: 0 | Q26: 0 | R26: 0 | S26: 0 | T26: 0 | U26: 0 | V26: =SUM(C26:U26) -> 0
C27: 0 | D27: 0.0063 | E27: 0 | F27: 0 | G27: 0 | H27: 0 | I27: 0 | J27: 0 | K27: 0 | L27: 0 | M27: 0 | N27: 0 | O27: 0 | P27: 0 | Q27: 0 | R27: 0 | S27: 0 | T27: 0 | U27: 0 | V27: =SUM(C27:U27) -> 0
B28: AD VALOREM | C28: =MAX(C19,C18)*C27 -> 0 | D28: =MAX(D19,D18)*D27 -> 0 | E28: =MAX(E19,E18)*E27 -> 0 | F28: =MAX(F19,F18)*F27 -> 0 | G28: =MAX(G19,G18)*G27 -> 0 | H28: =MAX(H19,H18)*H27 -> 0 | I28: =MAX(I19,I18)*I27 -> 0 | J28: =MAX(J19,J18)*J27 -> 0 | ... U28: =MAX(U19,U18)*U27 -> 0 | V28: =SUM(C28:U28) -> 0
B29: IGV | C29: =0.16*(MAX(C19,C18)+C28) -> 0 | D29: =0.16*(MAX(D19,D18)+D28) -> 0 | E29: =0.16*(MAX(E19,E18)+E28) -> 0 | F29: =0.16*(MAX(F19,F18)+F28) -> 0 | G29: =0.16*(MAX(G19,G18)+G28) -> 0 | H29: =0.16*(MAX(H19,H18)+H28) -> 0 | I29: =0.16*(MAX(I19,I18)+I28) -> 0 | J29: =0.16*(MAX(J19,J18)+J28) -> 0 | ... U29: =0.16*(MAX(U19,U18)+U28) -> 0 | V29: =SUM(C29:U29) -> 0
B30: IPM | C30: =0.02*(MAX(C19,C18)+C28) -> 0 | D30: =0.02*(MAX(D19,D18)+D28) -> 0 | E30: =0.02*(MAX(E19,E18)+E28) -> 0 | F30: =0.02*(MAX(F19,F18)+F28) -> 0 | G30: =0.02*(MAX(G19,G18)+G28) -> 0 | H30: =0.02*(MAX(H19,H18)+H28) -> 0 | I30: =0.02*(MAX(I19,I18)+I28) -> 0 | J30: =0.02*(MAX(J19,J18)+J28) -> 0 | ... U30: =0.02*(MAX(U19,U18)+U28) -> 0 | V30: =SUM(C30:U30) -> 0
B31: PERCEPCION | C31: =0.035*(MAX(C18,C19) +C28+C29+C30) -> 0 | D31: =0.035*(MAX(D18,D19) +D28+D29+D30) -> 0 | E31: =0.035*(MAX(E18,E19) +E28+E29+E30) -> 0 | F31: =0.035*(MAX(F18,F19) +F28+F29+F30) -> 0 | G31: =0.035*(MAX(G18,G19) +G28+G29+G30) -> 0 | H31: =0.035*(MAX(H18,H19) +H28+H29+H30) -> 0 | I31: =0.035*(MAX(I18,I19) +I28+I29+I30) -> 0 | J31: =0.035*(MAX(J18,J19) +J28+J29+J30) -> 0 | ... U31: =0.035*(MAX(U18,U19) +U28+U29+U30) -> 0 | V31: =SUM(C31:U31) -> 0
B32: TOTAL | C32: =SUM(C28:C31) -> 0 | D32: =SUM(D28:D31) -> 0 | E32: =SUM(E28:E31) -> 0 | F32: =SUM(F28:F31) -> 0 | G32: =SUM(G28:G31) -> 0 | H32: =SUM(H28:H31) -> 0 | I32: =SUM(I28:I31) -> 0 | J32: =SUM(J28:J31) -> 0 | ... V32: =SUM(V28:V31) -> 0
B37: Costos Destinos
B40: ITEM | C40: =C13*V40 -> 0 | D40: =D13*V40 -> 0 | E40: =E13*V40 -> 0 | F40: =F13*V40 -> 0 | G40: =G13*V40 -> 0 | H40: =H13*V40 -> 0 | I40: =I13*V40 -> 0 | J40: =J13*V40 -> 0 | K40: =K13*V40 -> 0 | L40: =L13*V40 -> 0 | M40: =M13*V40 -> 0 | N40: =N13*V40 -> 0 | O40: =O13*V40 -> 0 | P40: =P13*V40 -> 0 | Q40: =Q13*V40 -> 0 | R40: =R13*V40 -> 0 | S40: =S13*V40 -> 0 | T40: =T13*V40 -> 0 | U40: =U13*V40 -> 0 | V40: =IF(V7<1, Z7*0.4,Z7*0.4*V7) -> 0
B43: ITEM | C43: POSA RUEDAS O TOPES PARA RUEDAS | D43: CARTERAS PARA DAMA | E43: SCOOTER ELECTRICO PARA NIÑO | F43: ADAPTADOR USB SATA | G43: CASE PARA DISCO DURO | H43: CADDY 2.5" PARA COMPUTADORA | I43: MOTHERBOARD H61 PARA COMPUTADORA | J43: MOTHERBOARD H81 PARA COMPUTADORA | K43: TARJETA GRAFICA GT730 PARA COMPUTADORA | L43: TARJETA GRAFICA GTX750TI PARA COMPUTADORA | M43: AFEITADORA ELÉCTRICA CDH002-MN | N43: CAPA PARA BARBERIA | O43: AFEITADORA CLASICA AJUSTABLE | P43: BASE DE SOPORTE PARA MAQUINA DE AFEITAR | Q43: SET DE 50 HOJAS PARA AFEITAR | R43: EMBRAGUE DE LIBERACIÓN PARA BATERIA ACUSTICA | S43: ABRAZADERA PARA TABOR DE BATERÍA ACUSTICA | T43: SET DE SEGURO PARA PLATILLOS | U43: TUERCAS PARA PLATILLOS DE BATERIA | V43: Total
B44: COSTO TOTAL | C44: =SUM(C15,C40,C32,(C26)) -> 0 | D44: =SUM(D15,D40,D32,(D26)) -> 0 | E44: =SUM(E15,E40,E32,(E26)) -> 0 | F44: =SUM(F15,F40,F32,(F26)) -> 0 | G44: =SUM(G15,G40,G32,(G26)) -> 0 | H44: =SUM(H15,H40,H32,(H26)) -> 0 | I44: =SUM(I15,I40,I32,(I26)) -> 0 | J44: =SUM(J15,J40,J32,(J26)) -> 0 | ... U44: =SUM(U15,U40,U32,(U26)) -> 0 | V44: =SUM(C44:U44) -> 0
B45: CANTIDAD | C45: 400 | D45: 50 | E45: 10 | F45: 1000 | G45: 2000 | H45: 500 | I45: 500 | J45: 500 | K45: 20 | L45: 21 | M45: 1000 | N45: 1000 | O45: 450 | P45: 50 | Q45: 100 | R45: 20 | S45: 30 | T45: 50 | U45: 100
B46: COSTO UNITARIO | C46: =SUM(C44/C45) -> 0 | D46: =SUM(D44/D45) -> 0 | E46: =SUM(E44/E45) -> 0 | F46: =SUM(F44/F45) -> 0 | G46: =SUM(G44/G45) -> 0 | H46: =SUM(H44/H45) -> 0 | I46: =SUM(I44/I45) -> 0 | J46: =SUM(J44/J45) -> 0 | ... U46: =SUM(U44/U45) -> 0
B47: COSTO SOLES | C47: =C46*3.7 -> 0 | D47: =D46*3.7 -> 0 | E47: =E46*3.7 -> 0 | F47: =F46*3.7 -> 0 | G47: =G46*3.7 -> 0 | H47: =H46*3.7 -> 0 | I47: =I46*3.7 -> 0 | J47: =J46*3.7 -> 0 | ... U47: =U46*3.7 -> 0
