Workbook

Sheet 1
E3: PRO MUNDO COMEX S.A.C.
E4: RUC: 20612452432
E7: COTIZACION N002
B8: NOMBRE: | C8: BRYAN RUIZ | E8: SERVICIO: | F8: CARGA CONSOLIDADA | I8: N° CAJAS: | J8: 83
B9: APELLIDO: | E9: FECHA: | F9: 13/02/2025 | I9: PESO: | J9: 1370.4
B10: DNI/RUC: | C10: 47976981 | E10: ORIGEN: | F10: CHINA | I10: MEDIDA: | J10: 0
B11: TELEFONO: | C11: 929 610 511 | E11: CLIENTE: | F11: NUEVO | I11: VOLUMEN: | J11: 0
B13: CALCULO DE BASE IMPONIBLE | K13: MONTO | L13: MONEDA
B14: VALOR DE CARGA | K14: ='2'!D18 -> 0 | L14: USD
B15: FLETE INTERNACIONAL + SEGURO | K15: ='2'!D20 + '2'!D22 -> 0 | L15: USD
B16: VALOR CIF | K16: =SUM(K14:K15) -> 0 | L16: USD
B19: CALCULO DE TRIBUTOS | J19: % | K19: MONTO | L19: MONEDA
B20: ADVALOREM | J20: =MAX('2'!C33:C33) -> 0 | K20: ='2'!D34 -> 0 | L20: USD
B21: IGV | J21: 0.16 | K21: ='2'!D35 -> 0 | L21: USD
B22: IPM | J22: 0.02 | K22: ='2'!D36 -> 0 | L22: USD
B23: SUB TOTAL | K23: =SUM(K20:K22) -> 0 | L23: USD
B25: PERCEPCIÓN | J25: 3.5% | K25: ='2'!D37 -> 0 | L25: USD
B26: TOTAL | K26: =K23+K25 -> 0 | L26: USD
B28: RESUMEN DE COTIZACIÓN | K28: MONTO | L28: MONEDA
B29: VALOR DE CARGA (PAGO AL PROVEEDOR) | K29: =K14 -> 0 | L29: USD
B30: SERVICIO DE IMPORTACIÓN (ORIGEN -FLETE - DESTINO) | K30: ='2'!D18+'2'!D45 -> 0 | L30: USD
B31: IMPUESTOS | K31: =K26 -> 0 | L31: USD
B32: MONTO TOTAL | K32: =SUM(K29:K31) -> 0 | L32: USD
B34: SIMULACIÓN DEL PRECIO PUESTO EN PERÚ POR PIEZA
B35: # ITEM | C35: NOMBRE PRODUCTO | F35: CANTIDAD | G35: COSTO UNI. | I35: PRECIO U. | J35: TOTAL | K35: PRECIO UNIT. (SOLES)
B36: 1 | C36: hola | F36: ='2'!C17 -> 0 | G36: ='2'!C15 -> 0 | I36: ='2'!C53 -> 0 | J36: ='2'!C51 -> 0 | K36: ='2'!C54 -> 0
B42: NOTAS:
B43: *Las fechas brindadas son estimadas, estan sujetas a variación.
B44: *No se emite comprobante por concepto de "PERCEPCIÓN, ANTI DUMPING, GESTIÓN DE COMPRA"
B45: *A nosotros se nos pagan los Gastos Logísticos + Impuestos una semana antes de que el contenedor
B46: llegue al puerto del Callao.
B47: *El tipo de cambio referencial usado para la conversión a soles es del 3.70
D50: PRO MUNDO COMEX S.A.C.
D51: RUC: 20612452432
B54: TÉRMINOS Y CONDICIONES:
B56: 1. Todos los pagos se realizan en dólares.
B57: 2.Todas las marcas de los productos deben ser verificadas por el cliente,
B58: No se aceptan marcas con medidas de frontera.
B59: 3. No somos responsables de retraso del proveedor para entregar la carga.
B60: 4. La carga deberá llegar al almacén –Yiwu en el rango de fecha indicado por su asesor.
...

Sheet 2
B1: Calculo de Tributos
B4: N.Proveedor | C4: chino
B5: N° Cajas | C5: =SUM(C12:C12) -> 0 | D5: =SUM(C12:C12) -> 0
B6: Peso(KG) | C6: =SUM(C13:C13) -> 0 | D6: =SUM(C13:C13) -> 0
B7: Medida
B8: VOL. X PROVEEDOR
B11: Nombres | C11: hola
B12: Cantidad Cajones | C12: 83 | D12: =SUM(C12:C12) -> 0
B13: Peso | C13: 1370.4 | D13: =SUM(C13:C13) -> 0
B14: TOTAL CBM | D14: =SUM(C14:C14) -> 0
B15: Valor Unitario | D15: =SUM(C15:C15) -> 0
B16: Valoracion
B17: Cantidad | D17: =SUM(C17:C17) -> 0
B18: Valor FOB | C18: =C15*C17 -> 0 | D18: =SUM(C18:C18) -> 0
B19: Distribucion % | C19: =C18/D18 -> 0
B20: Flete | C20: =D20*C19 -> 0 | D20: =D14*0.6*300 -> 0
B21: Valor CFR | C21: =C18+C20 -> 0 | D21: =SUM(C21:C21) -> 0
B22: Seguro | C22: =D22*C19 -> 0 | D22: =IF(D21>5000,100,50) -> 0
B23: Valor CIF | C23: =C21+C22 -> 0
B28: Tributos Aplicables
B31: ANTIDUMPING | C31: =*C17 -> 0 | D31: =SUM(C31:C31) -> 0
C33: =
B34: AD VALOREM | C34: =*C23 -> 0 | D34: =SUM(C34:C34) -> 0
B35: IGB 16% | C35: =C23*0.16 -> 0 | D35: =SUM(C35:C35) -> 0
B36: IPM 2% | C36: =C23*0.02 -> 0 | D36: =SUM(C36:C36) -> 0
B37: PERCEPCION | C37: =C23* -> 0 | D37: =SUM(C36:C37) -> 0
B38: TOTAL | C38: =SUM(C34:C37) -> 0 | D38: =SUM(C38:C38) -> 0
T39: TC
T40: 3.7
B42: COSTOS DESTINOS
B45: ITEM | C45: =D45*C19 -> 0 | D45: =D14*0.4*300 -> 0
B48: COSTO TOTAL DE IMPORTACIÓN
B50: ITEM | C50: hola
B51: COSTO TOTAL | C51: =C21+C31+C38+C45 -> 0
B52: CANTIDAD | C52: =C17 -> 0
B53: COSTO UNITARIO | C53: =C51/C52 -> 0
B54: COSTO SOLES | C54: =C53*T40 -> 0
