Workbook

Sheet 1
E3: PRO MUNDO COMEX S.A.C.
E4: RUC: 20612452432
E7: COTIZACION N002
B8: NOMBRE: | C8: Percy Sullca Tito | E8: SERVICIO: | F8: CARGA CONSOLIDADA | I8: N° CAJAS: | J8: =+'2'!F7 -> 0
B9: APELLIDO: | E9: FECHA: | F9: =+TODAY() -> 45727 | I9: PESO: | J9: Kg
B10: DNI/RUC: | C10: 10518506 | E10: ORIGEN: | F10: CHINA | I10: MEDIDA:
B11: TELEFONO: | C11: 972 896 791 | E11: CLIENTE: | F11: NUEVO | I11: CBM | J11: ='2'!L7 -> 1.24
B13: CALCULO DE BASE IMPONIBLE | K13: MONTO | L13: MONEDA
B14: VALOR DE CARGA | K14: ='2'!L11 -> 1888.5 | L14: USD
B15: FLETE INTERNACIONAL + SEGURO | K15: ='2'!L14 + '2'!L17 -> 328.99 | L15: USD
B16: VALOR CIF | K16: =SUM(K14:K15) -> 2217.49 | L16: USD
B19: CALCULO DE TRIBUTOS | J19: % | K19: MONTO | L19: MONEDA
B20: ADVALOREM | J20: =MAX('2'!C27:K27) -> 0.0063 | K20: ='2'!L28 -> 7.223706 | L20: USD | N20: Hola Percy Sullca Tito 😁 un gusto saludarte! A continuación te envío la cotización final de tu importación📋📦. 🙋‍♂️ PAGO PENDIENTE : ☑️Costo CBM: $445.5 ☑️Impuestos: $499.56 ☑️ Total: $945.06 Pronto le aviso nuevos avances, que tengan buen día🚢 Último día de pago:
B21: IGV | J21: 0.16 | K21: ='2'!L29 -> 355.96059 | L21: USD
B22: IPM | J22: 0.02 | K22: ='2'!L30 -> 44.495074 | L22: USD
B23: SUB TOTAL | K23: =SUM(K20:K22) -> 407.67937 | L23: USD
B25: PERCEPCIÓN | J25: 3.5% | K25: ='2'!L31 -> 91.882328 | L25: USD
B26: TOTAL | K26: =K23+K25 -> 499.5617 | L26: USD
B28: RESUMEN DE COTIZACIÓN | K28: MONTO | L28: MONEDA
B29: VALOR DE CARGA (PAGO AL PROVEEDOR) | K29: =K14 -> 1888.5 | L29: USD
B30: SERVICIO DE IMPORTACIÓN (ORIGEN -FLETE - DESTINO) | K30: =IF('2'!P7<1, '2'!P7*J11, '2'!P7*J11) -> 465 | L30: USD
B31: IMPUESTOS | K31: =K26 -> 499.5617 | L31: USD
B32: MONTO TOTAL | K32: =SUM(K29:K31) -> 2853.0617 | L32: USD
B34: SIMULACIÓN DEL PRECIO PUESTO EN PERÚ POR PIEZA
B35: # ITEM | C35: NOMBRE PRODUCTO | F35: CANTIDAD | G35: COSTO UNI. | I35: PRECIO U. | J35: TOTAL | K35: PRECIO UNIT. (SOLES)
B36: 1 | C36: SOPORTE DE CAMPANA DE TAMBOR | F36: ='2'!C10 -> 10 | G36: ='2'!C8 -> 4 | I36: ='2'!C46 -> 6.02 | J36: ='2'!C44 -> 60.244096 | K36: ='2'!C47 -> 22.27
B37: 2 | C37: PANDERETA PARA TAROLA DE BATERIA | F37: ='2'!D10 -> 5 | G37: ='2'!D8 -> 5 | I37: ='2'!D46 -> 7.53 | J37: ='2'!D44 -> 37.65964 | K37: ='2'!D47 -> 27.86
B38: 3 | C38: MAZO PARA PEDAL DE BOMBO MODELO 1 | F38: ='2'!E10 -> 10 | G38: ='2'!E8 -> 4.5 | I38: ='2'!E46 -> 6.78 | J38: ='2'!E44 -> 67.775581 | K38: ='2'!E47 -> 25.09
B39: 4 | C39: MAZO PARA PEDAL DE BOMBO MODELO 2 | F39: ='2'!F10 -> 12 | G39: ='2'!F8 -> 1 | I39: ='2'!F46 -> 1.51 | J39: ='2'!F44 -> 18.08222 | K39: ='2'!F47 -> 5.59
B40: 5 | C40: SOPORTE PARA BAQUETAS | F40: ='2'!G10 -> 20 | G40: ='2'!G8 -> 3.5 | I40: ='2'!G46 -> 5.27 | J40: ='2'!G44 -> 105.43522 | K40: ='2'!G47 -> 19.5
B41: 6 | C41: ARO DE TAMBOR PARA BATERÍA | F41: ='2'!H10 -> 13 | G41: ='2'!H8 -> 19.076923 | I41: ='2'!H46 -> 28.73 | J41: ='2'!H44 -> 373.51051 | K41: ='2'!H47 -> 106.3
B42: 7 | C42: BAQUETAS PARA BATERIA | F42: ='2'!I10 -> 120 | G42: ='2'!I8 -> 3.4 | I42: ='2'!I46 -> 5.12 | J42: ='2'!I44 -> 614.48468 | K42: ='2'!I47 -> 18.94
B43: 8 | C43: GUARDAFANDO DELANTERO PARA CAMIÓN | F43: ='2'!J10 -> 5 | G43: ='2'!J8 -> 12.8 | I43: ='2'!J46 -> 19.28 | J43: ='2'!J44 -> 96.39411 | K43: ='2'!J47 -> 71.34
B44: 9 | C44: BOLSO PARA MUJER | F44: ='2'!K10 -> 150 | G44: ='2'!K8 -> 6.51 | I44: ='2'!K46 -> 9.86 | J44: ='2'!K44 -> 1479.5156 | K44: ='2'!K47 -> 36.48
B45: TOTAL | F45: =SUM(F36:F44) -> 345 | J45: =SUM(J36:J44) -> 2853.1017
B46: *No se emite comprobante por concepto de "PERCEPCIÓN, ANTI DUMPING, GESTIÓN DE COMPRA"
B47: *A nosotros se nos pagan los Gastos Logísticos + Impuestos una semana antes de que el contenedor
B48: llegue al puerto del Callao.
B49: *El tipo de cambio referencial usado para la conversión a soles es del 3.70
D52: PRO MUNDO COMEX S.A.C.
...

Sheet 2
B3: Calculo de Tributos
B5: Nombres | C5: SOPORTE DE CAMPANA DE TAMBOR | D5: PANDERETA PARA TAROLA DE BATERIA | E5: MAZO PARA PEDAL DE BOMBO MODELO 1 | F5: MAZO PARA PEDAL DE BOMBO MODELO 2 | G5: SOPORTE PARA BAQUETAS | H5: ARO DE TAMBOR PARA BATERÍA | I5: BAQUETAS PARA BATERIA | J5: GUARDAFANDO DELANTERO PARA CAMIÓN | K5: BOLSO PARA MUJER | L5: Total
B6: Peso | C6: 0 | D6: 0 | E6: 0 | F6: 0 | G6: 0 | H6: 0 | I6: 0 | J6: 0 | K6: 0 | O6: Tipo Cliente | P6: Tarifa
B7: Valor CBM | C7: 0 | D7: 0 | E7: 0 | F7: 0 | G7: 0 | H7: 0 | I7: 0 | J7: 0 | K7: 0 | L7: 1.24 | O7: NUEVO | P7: 375
B8: Valor Unitario | C8: 4 | D8: 5 | E8: 4.5 | F8: 1 | G8: 3.5 | H8: 19.076923 | I8: 3.4 | J8: 12.8 | K8: 6.51
B9: Valoracion | C9: 0 | D9: 0 | E9: 0 | F9: 0 | G9: 0 | H9: 0 | I9: 0 | J9: 0 | K9: 0
B10: Cantidad | C10: 10 | D10: 5 | E10: 10 | F10: 12 | G10: 20 | H10: 13 | I10: 120 | J10: 5 | K10: 150 | L10: =SUM(C10:K10) -> 345
B11: Valor FOB | C11: =C8*C10 -> 40 | D11: =D8*D10 -> 25 | E11: =E8*E10 -> 45 | F11: =F8*F10 -> 12 | G11: =G8*G10 -> 70 | H11: =H8*H10 -> 248 | I11: =I8*I10 -> 408 | J11: =J8*J10 -> 64 | K11: =K8*K10 -> 976.5 | L11: =SUM(C11:K11) -> 1888.5
B12: Valor FOB Valoracion | C12: =C10*C9 -> 0 | D12: =D10*D9 -> 0 | E12: =E10*E9 -> 0 | F12: =F10*F9 -> 0 | G12: =G10*G9 -> 0 | H12: =H10*H9 -> 0 | I12: =I10*I9 -> 0 | J12: =J10*J9 -> 0 | K12: =K10*K9 -> 0 | L12: =SUM(C12:K12) -> 0
B13: Distribucion % | C13: =C11/L11 -> 0.021180831 | D13: =D11/L11 -> 0.01323802 | E13: =E11/L11 -> 0.023828435 | F13: =F11/L11 -> 0.0063542494 | G13: =G11/L11 -> 0.037066455 | H13: =H11/L11 -> 0.13132115 | I13: =I11/L11 -> 0.21604448 | J13: =J11/L11 -> 0.03388933 | K13: =K11/L11 -> 0.51707705
B14: Flete | C14: =ROUNDUP(L14*C13,2) -> 5.91 | D14: =ROUNDUP(L14*D13,2) -> 3.7 | E14: =ROUNDUP(L14*E13,2) -> 6.65 | F14: =ROUNDUP(L14*F13,2) -> 1.78 | G14: =ROUNDUP(L14*G13,2) -> 10.35 | H14: =ROUNDUP(L14*H13,2) -> 36.64 | I14: =ROUNDUP(L14*I13,2) -> 60.28 | J14: =ROUNDUP(L14*J13,2) -> 9.46 | K14: =ROUNDUP(L14*K13,2) -> 144.27 | L14: =IF(L7<1, ROUNDUP(P7*0.6, 0), ROUNDUP(P7*0.6*L7, 0)) -> 279
B15: Valor CFR | C15: =ROUNDUP(C11+C14,2) -> 45.91 | D15: =ROUNDUP(D11+D14,2) -> 28.7 | E15: =ROUNDUP(E11+E14,2) -> 51.65 | F15: =ROUNDUP(F11+F14,2) -> 13.78 | G15: =ROUNDUP(G11+G14,2) -> 80.35 | H15: =ROUNDUP(H11+H14,2) -> 284.64 | I15: =ROUNDUP(I11+I14,2) -> 468.28 | J15: =ROUNDUP(J11+J14,2) -> 73.46 | K15: =ROUNDUP(K11+K14,2) -> 1120.77 | L15: =SUM(C15:K15) -> 2167.54
B16: CFR Valorizado | C16: =ROUNDUP(C12+C14,2) -> 5.91 | D16: =ROUNDUP(D12+D14,2) -> 3.7 | E16: =ROUNDUP(E12+E14,2) -> 6.65 | F16: =ROUNDUP(F12+F14,2) -> 1.78 | G16: =ROUNDUP(G12+G14,2) -> 10.35 | H16: =ROUNDUP(H12+H14,2) -> 36.64 | I16: =ROUNDUP(I12+I14,2) -> 60.28 | J16: =ROUNDUP(J12+J14,2) -> 9.46 | K16: =ROUNDUP(K12+K14,2) -> 144.27 | L16: =SUM(C16:K16) -> 279.04
B17: Seguro | C17: =IF(L15>5000,ROUND(100*C13,2),ROUND(50*C13,2)) -> 1.06 | D17: =IF(L15>5000,ROUND(100*D13,2),ROUND(50*D13,2)) -> 0.66 | E17: =IF(L15>5000,ROUND(100*E13,2),ROUND(50*E13,2)) -> 1.19 | F17: =IF(L15>5000,ROUND(100*F13,2),ROUND(50*F13,2)) -> 0.32 | G17: =IF(L15>5000,ROUND(100*G13,2),ROUND(50*G13,2)) -> 1.85 | H17: =IF(L15>5000,ROUND(100*H13,2),ROUND(50*H13,2)) -> 6.57 | I17: =IF(L15>5000,ROUND(100*I13,2),ROUND(50*I13,2)) -> 10.8 | J17: =IF(L15>5000,ROUND(100*J13,2),ROUND(50*J13,2)) -> 1.69 | K17: =IF(L15>5000,ROUND(100*K13,2),ROUND(50*K13,2)) -> 25.85 | L17: =SUM(C17:K17) -> 49.99
B18: Valor CIF | C18: =ROUNDUP(C15+C17,2) -> 46.97 | D18: =ROUNDUP(D15+D17,2) -> 29.36 | E18: =ROUNDUP(E15+E17,2) -> 52.84 | F18: =ROUNDUP(F15+F17,2) -> 14.1 | G18: =ROUNDUP(G15+G17,2) -> 82.2 | H18: =ROUNDUP(H15+H17,2) -> 291.21 | I18: =ROUNDUP(I15+I17,2) -> 479.08 | J18: =ROUNDUP(J15+J17,2) -> 75.15 | K18: =ROUNDUP(K15+K17,2) -> 1146.62 | L18: =SUM(C18:K18) -> 2217.53
B19: CIF Valorizado | C19: =ROUNDUP(C16+C17,2) -> 6.97 | D19: =ROUNDUP(D16+D17,2) -> 4.36 | E19: =ROUNDUP(E16+E17,2) -> 7.84 | F19: =ROUNDUP(F16+F17,2) -> 2.1 | G19: =ROUNDUP(G16+G17,2) -> 12.2 | H19: =ROUNDUP(H16+H17,2) -> 43.21 | I19: =ROUNDUP(I16+I17,2) -> 71.08 | J19: =ROUNDUP(J16+J17,2) -> 11.15 | K19: =ROUNDUP(K16+K17,2) -> 170.12 | L19: =SUM(C19:K19) -> 329.03
B23: Tributos Aplicables
B26: ANTIDUMPING | C26: 0 | D26: 0 | E26: 0 | F26: 0 | G26: 0 | H26: 0 | I26: 0 | J26: 0 | K26: 0 | L26: =SUM(C26:K26) -> 0
C27: 0 | D27: 0 | E27: 0 | F27: 0 | G27: 0 | H27: 0 | I27: 0 | J27: 0 | K27: 0.0063 | L27: =SUM(C27:K27) -> 0.0063
B28: AD VALOREM | C28: =MAX(C19,C18)*C27 -> 0 | D28: =MAX(D19,D18)*D27 -> 0 | E28: =MAX(E19,E18)*E27 -> 0 | F28: =MAX(F19,F18)*F27 -> 0 | G28: =MAX(G19,G18)*G27 -> 0 | H28: =MAX(H19,H18)*H27 -> 0 | I28: =MAX(I19,I18)*I27 -> 0 | J28: =MAX(J19,J18)*J27 -> 0 | K28: =MAX(K19,K18)*K27 -> 7.223706 | L28: =SUM(C28:K28) -> 7.223706
B29: IGV | C29: =0.16*(MAX(C19,C18)+C28) -> 7.5152 | D29: =0.16*(MAX(D19,D18)+D28) -> 4.6976 | E29: =0.16*(MAX(E19,E18)+E28) -> 8.4544 | F29: =0.16*(MAX(F19,F18)+F28) -> 2.256 | G29: =0.16*(MAX(G19,G18)+G28) -> 13.152 | H29: =0.16*(MAX(H19,H18)+H28) -> 46.5936 | I29: =0.16*(MAX(I19,I18)+I28) -> 76.6528 | J29: =0.16*(MAX(J19,J18)+J28) -> 12.024 | K29: =0.16*(MAX(K19,K18)+K28) -> 184.61499 | L29: =SUM(C29:K29) -> 355.96059
B30: IPM | C30: =0.02*(MAX(C19,C18)+C28) -> 0.9394 | D30: =0.02*(MAX(D19,D18)+D28) -> 0.5872 | E30: =0.02*(MAX(E19,E18)+E28) -> 1.0568 | F30: =0.02*(MAX(F19,F18)+F28) -> 0.282 | G30: =0.02*(MAX(G19,G18)+G28) -> 1.644 | H30: =0.02*(MAX(H19,H18)+H28) -> 5.8242 | I30: =0.02*(MAX(I19,I18)+I28) -> 9.5816 | J30: =0.02*(MAX(J19,J18)+J28) -> 1.503 | K30: =0.02*(MAX(K19,K18)+K28) -> 23.076874 | L30: =SUM(C30:K30) -> 44.495074
B31: PERCEPCION | C31: =0.035*(MAX(C18,C19) +C28+C29+C30) -> 1.939861 | D31: =0.035*(MAX(D18,D19) +D28+D29+D30) -> 1.212568 | E31: =0.035*(MAX(E18,E19) +E28+E29+E30) -> 2.182292 | F31: =0.035*(MAX(F18,F19) +F28+F29+F30) -> 0.58233 | G31: =0.035*(MAX(G18,G19) +G28+G29+G30) -> 3.39486 | H31: =0.035*(MAX(H18,H19) +H28+H29+H30) -> 12.026973 | I31: =0.035*(MAX(I18,I19) +I28+I29+I30) -> 19.786004 | J31: =0.035*(MAX(J18,J19) +J28+J29+J30) -> 3.103695 | K31: =0.035*(MAX(K18,K19) +K28+K29+K30) -> 47.653745 | L31: =SUM(C31:K31) -> 91.882328
B32: TOTAL | C32: =SUM(C28:C31) -> 10.394461 | D32: =SUM(D28:D31) -> 6.497368 | E32: =SUM(E28:E31) -> 11.693492 | F32: =SUM(F28:F31) -> 3.12033 | G32: =SUM(G28:G31) -> 18.19086 | H32: =SUM(H28:H31) -> 64.444773 | I32: =SUM(I28:I31) -> 106.0204 | J32: =SUM(J28:J31) -> 16.630695 | ... L32: =SUM(L28:L31) -> 499.5617
B37: Costos Destinos
B40: ITEM | C40: =C13*L40 -> 3.9396346 | D40: =D13*L40 -> 2.4622716 | E40: =E13*L40 -> 4.432089 | F40: =F13*L40 -> 1.1818904 | G40: =G13*L40 -> 6.8943606 | H40: =H13*L40 -> 24.425735 | I40: =I13*L40 -> 40.184273 | J40: =J13*L40 -> 6.3034154 | K40: =K13*L40 -> 96.17633 | L40: =IF(L7<1, ROUNDUP(P7*0.4, 0), ROUNDUP(P7*0.4*L7, 0)) -> 186
B43: ITEM | C43: SOPORTE DE CAMPANA DE TAMBOR | D43: PANDERETA PARA TAROLA DE BATERIA | E43: MAZO PARA PEDAL DE BOMBO MODELO 1 | F43: MAZO PARA PEDAL DE BOMBO MODELO 2 | G43: SOPORTE PARA BAQUETAS | H43: ARO DE TAMBOR PARA BATERÍA | I43: BAQUETAS PARA BATERIA | J43: GUARDAFANDO DELANTERO PARA CAMIÓN | K43: BOLSO PARA MUJER | L43: Total
B44: COSTO TOTAL | C44: =SUM(C15,C40,C32,(C26*C10)) -> 60.244096 | D44: =SUM(D15,D40,D32,(D26*D10)) -> 37.65964 | E44: =SUM(E15,E40,E32,(E26*E10)) -> 67.775581 | F44: =SUM(F15,F40,F32,(F26*F10)) -> 18.08222 | G44: =SUM(G15,G40,G32,(G26*G10)) -> 105.43522 | H44: =SUM(H15,H40,H32,(H26*H10)) -> 373.51051 | I44: =SUM(I15,I40,I32,(I26*I10)) -> 614.48468 | J44: =SUM(J15,J40,J32,(J26*J10)) -> 96.39411 | K44: =SUM(K15,K40,K32,(K26*K10)) -> 1479.5156 | L44: =SUM(C44:K44) -> 2853.1017
B45: CANTIDAD | C45: 10 | D45: 5 | E45: 10 | F45: 12 | G45: 20 | H45: 13 | I45: 120 | J45: 5 | K45: 150
B46: COSTO UNITARIO | C46: =ROUND(SUM(C44/C45),2) -> 6.02 | D46: =ROUND(SUM(D44/D45),2) -> 7.53 | E46: =ROUND(SUM(E44/E45),2) -> 6.78 | F46: =ROUND(SUM(F44/F45),2) -> 1.51 | G46: =ROUND(SUM(G44/G45),2) -> 5.27 | H46: =ROUND(SUM(H44/H45),2) -> 28.73 | I46: =ROUND(SUM(I44/I45),2) -> 5.12 | J46: =ROUND(SUM(J44/J45),2) -> 19.28 | K46: =ROUND(SUM(K44/K45),2) -> 9.86
B47: COSTO SOLES | C47: =ROUND(C46*3.7,2) -> 22.27 | D47: =ROUND(D46*3.7,2) -> 27.86 | E47: =ROUND(E46*3.7,2) -> 25.09 | F47: =ROUND(F46*3.7,2) -> 5.59 | G47: =ROUND(G46*3.7,2) -> 19.5 | H47: =ROUND(H46*3.7,2) -> 106.3 | I47: =ROUND(I46*3.7,2) -> 18.94 | J47: =ROUND(J46*3.7,2) -> 71.34 | K47: =ROUND(K46*3.7,2) -> 36.48
