Workbook

Sheet 1
W3: TIPO DE CLIENTE
W4: ANTIGUO
W5: NUEVO
W6: SOCIO
D7: COTIZACION Nº20240000001 | W7: PILOTO
A8: NOMBRE: | B8: BRYAN RUIZ | D8: SERVICIO: | E8: CARGA CONSOLIDADA | H8: N° CAJAS: | I8: =+'2'!E5 -> 83 | W8: MANUAL
A9: DNI/RUC: | B9: 47976981 | D9: FECHA: | E9: =+TODAY() -> 45736 | H9: PESO: | I9: =+'2'!E6 -> 1470.4 | S9: TOTAL CBM | T9: TARIFA
A10: CORREO: | B10: bryanruizbellido@gmail.com | D10: ORIGEN: | E10: CHINA | H10: MEDIDA | I10: 0 | J10: 0 | K10: 0 | R10: NUEVO | S10: {=IF('1'!$I$11<0.59,280,IF('1'!$I$11<1,375,IF('1'!$I$11<=2.09,375*'1'!$I$11,IF('1'!$I$11<=3.09,350*'1'!$I$11,IF('1'!$I$11<=4.09,325*'1'!$I$11,IF('1'!$I$11>4.09,300*'1'!$I$11,ERROR))))))} -> 3403.8 | T10: =IF($I$11<1,S10,S10/$I$11) -> 300 | W10: NUEVO | X10: ANTIGUO | Y10: SOCIO
A11: TELEFONO: | B11: 51934958839 | D11: CLIENTE: | E11: NUEVO | H11: VOLUMEN: | I11: =+'2'!E8 -> 11.346 | R11: ANTIGUO | S11: {=IF('1'!$I$11<0.59,260,IF('1'!$I$11<1,350,IF('1'!$I$11<2.09,350*'1'!$I$11,IF('1'!$I$11<3.09,325*'1'!$I$11,IF('1'!$I$11<4.09,'1'!$I$11*300,IF('1'!$I$11>4.09,280*'1'!$I$11,ERROR))))))} -> 3176.88 | T11: =IF($I$11<1,S11,S11/$I$11) -> 280 | V11: 0-0.59 | W11: 280 | X11: 260 | Y11: 250
R12: MANUAL | S12: =T12*I11 -> 0 | T12: 0 | V12: 0.59-1 | W12: 375 | X12: 350
A13: CALCULO DE BASE IMPONIBLE | J13: MONTO | K13: MONEDA | R13: SOCIO | S13: =IF('1'!$I$11<1,250,IF('1'!$I$11<4,250*'1'!$I$11,IF('1'!$I$11<=10,250*'1'!$I$11,IF('1'!$I$11>10,250*'1'!$I$11,"VERIFICA EL CBM")))) -> 2836.5 | T13: =IF($I$11<1,S13,S13/I$11) -> 250 | V13: 1-2.09 | W13: 375 | X13: 350
A14: VALOR DE CARGA | J14: ='2'!E18 -> 15985 | K14: USD | R14: PILOTO | S14: =IF('1'!$I$11<1,250,250*'1'!$I$11) -> 2836.5 | T14: =IF($I$11<1,S14,S14/$I$11) -> 250 | V14: 2.1-3.1 | W14: 350 | X14: 325
A15: FLETE INTERNACIONAL + SEGURO | J15: =IF(I11<1,'2'!E21+'2'!E24,60%*(T16*I11)+'2'!E24) -> 2142.28 | K15: USD | V15: 3.1-4.1 | W15: 325 | X15: 300
A16: VALOR CIF | J16: =SUM(J14:J15) -> 18127.28 | K16: USD | R16: Tarifa | S16: =E11 -> NUEVO | T16: =VLOOKUP(S16,R10:T14,3,0) -> 300 | V16: 4.1- + | W16: 300 | X16: 280
A19: CALCULO DE TRIBUTOS | I19: % | J19: MONTO | K19: MONEDA
A20: ADVALOREM | I20: =MAX('2'!C33:C33) -> 0 | J20: ='2'!E34 -> 0 | K20: USD | N20: TARIFA
A21: IGV | I21: 0.16 | J21: ='2'!E35 -> 2900.3648 | K21: USD | N21: =J31/I11 -> 300
A22: IPM | I22: 0.02 | J22: ='2'!E36 -> 362.5456 | K22: USD
A23: ANTIDUMPING | I23: =MAX('2'!C30:C30) -> 0 | J23: ='2'!E31 -> 0 | K23: USD
A24: SUB TOTAL | J24: =SUM(J20:J23) -> 3262.9104 | K24: USD
A26: PERCEPCIÓN | I26: 3.5% | J26: ='2'!E37 -> 748.65666 | K26: USD
A27: TOTAL | J27: =J24+J26 -> 4011.5671 | K27: USD
A29: RESUMEN DE COTIZACIÓN | J29: MONTO | K29: MONEDA
A30: VALOR DE CARGA (PAGO AL PROVEEDOR) | J30: =J14 -> 15985 | K30: USD
A31: SERVICIO DE IMPORTACIÓN (ORIGEN -FLETE - DESTINO) | J31: =IF(I11<1,T16,T16*I11) -> 3403.8 | K31: USD | L31: MONTO
A32: IMPUESTOS | J32: =J27 -> 4011.5671 | K32: USD
A33: MONTO TOTAL | J33: =SUM(J30:J32) -> 23400.367 | K33: USD | M33: RESUMEN DE COSTOS UNITARIOS
A35: SIMULACIÓN DEL PRECIO PUESTO EN PERÚ POR PIEZA | M35: # ITEM | N35: NOMBRE PRODUCTO | O35: VALOR CHINA USD | P35: VALOR PERU USD | Q35: VALOR PERU SOLES
A36: # ITEM | B36: NOMBRE PRODUCTO | E36: CANTIDAD | F36: COSTO UNI. | H36: PRECIO U. | I36: TOTAL | J36: PRECIO UNIT. (SOLES)
A37: 1 | B37: =+'2'!$C$11 -> Productos variados | E37: =+'2'!$C$52 -> 110182 | F37: =+'2'!$C$15 -> 0.072539072 | H37: =+'2'!$C$53 -> 0.10618961 | I37: =+E37*H37 -> 11700.184 | J37: =H37*3.8 -> 0.40352052 | M37: 1 | N37: =+B37 -> Productos variados | O37: =+F37 -> 0.072539072 | P37: =+H37 -> 0.10618961 | Q37: =P37*3.8 -> 0.40352052
A38: TOTAL | E38: =+SUM(E37:E37) -> 110182 | I38: =+SUM(I37:I37) -> 11700.184
M39: RESUMEN DE PAGOS DE SERVICIO DE IMPORTACIÓN | P39: FECHAS:
A40: NOTAS:
A41: *Las fechas brindadas son estimadas, estan sujetas a variación. | M41: PRIMER PAGO | O41: =+J31 -> 3403.8 | P41: Servicio de Consolidado antes del Zarpe 23/12
A42: *No se emite comprobante por concepto de "PERCEPCIÓN, ANTI DUMPING, GESTIÓN DE COMPRA" | M42: SEGUNDO PAGO | O42: =+J32 -> 4011.5671 | P42: Pago de Impuestos antes del Arribo 15/02
A43: *A nosotros se nos pagan el Servicio de Importación + Impuestos una semana antes de que el contenedor
A44: llegue al puerto del Callao. | M44: INVERSION TOTAL | O44: =+O41+O42 -> 7415.3671 | P44: Incluye Valor de Carga + Servicio de Consolidado + Pago de Impuestos
A45: *El cálculo de Impuestos puede variar por parte de Aduanas.
A46: *Si la carga ocupa más volumen de lo cotizado, se le tendrá que actualizar su cotización.
A47: *Habrá un costo extra del servicio del *monta cargas* en Lima (aplica para los Pallets)
...

Sheet 2
B1: CALCULOS DE TRIBUTOS
C3: BR04-1 | E3: TOTALES
B4: N PROVEEDOR | C4: 1 | D4: 2 | E4: =COUNT(C4:C4) -> 1
B5: N° CAJAS: | C5: 83 | D5: 10 | E5: =SUM(C5:C5) -> 83
B6: PESO (KG) | C6: 1370.4 | D6: 100 | E6: =SUM(C6:D7) -> 1470.4
B7: MEDIDA | C7: 0 | D7: 0
B8: VOL. X PROVEEDOR | C8: 9.776 | D8: 1.57 | E8: =SUM(C8:D9) -> 11.346
C10: 1 | D10: 2
B11: NOMBRE | C11: Productos variados | E11: TOTAL
B12: CANTIDAD CAJONES | E12: =SUM(C12:C12) -> 0
B13: PESO (KG) | E13: =SUM(C13:C13) -> 0
B14: TOTAL CBM | E14: =SUM(C14:C14) -> 0
B15: VALOR UNITARIO | C15: =7992.5/C17 -> 0.072539072 | D15: =7992.5/D17 -> 0.072538413
B16: VALOR ZAPATILLAS | H16: ='1'!E11 -> NUEVO | M16: TARIFA | N16: TARIFA | O16: 0.6 | P16: 0.4
B17: CANTIDAD | C17: 110182 | D17: 110183 | E17: =SUM(C17:D17) -> 220365 | L17: ='1'!R10 -> NUEVO | M17: ='1'!S10 -> 3403.8 | N17: ='1'!T10 -> 300 | O17: =$O$16*M17 -> 2042.28
B18: VALOR FOB | C18: =C15*C17 -> 7992.5 | D18: =D15*D17 -> 7992.5 | E18: =SUM(C18:D18) -> 15985 | L18: ='1'!R11 -> ANTIGUO | M18: ='1'!S11 -> 3176.88 | N18: ='1'!T11 -> 280 | O18: =$O$16*M18 -> 1906.128
B19: VALOR FOB | C19: =(MAX(C15:C16))*C17 -> 7992.5 | D19: =(MAX(D15:D16))*D17 -> 7992.5 | E19: =SUM(C19:C19) -> 7992.5 | L19: ='1'!R12 -> MANUAL | M19: ='1'!S12 -> 0 | N19: ='1'!T12 -> 0 | O19: =$O$16*M19 -> 0
B20: DISTRIBUCIÓN % | C20: =C18/$E$18 -> 0.5 | D20: =D18/$E$18 -> 0.5 | E20: TOTAL | L20: ='1'!R13 -> SOCIO | M20: ='1'!S13 -> 2836.5 | N20: ='1'!T13 -> 250 | O20: =$O$16*M20 -> 1701.9
B21: FLETE | C21: =$E$21*C20 -> 1021.14 | D21: =$E$21*D20 -> 1021.14 | E21: =IF(M19=0,IF('1'!E11="NUEVO",'2'!M17*60%,IF('1'!E11="ANTIGUO",'2'!M18*60%,IF('1'!E11="SOCIO",60%*(250*'1'!I11),IF('1'!E11="PILOTO",60%*(250*'1'!I11),IF('2'!M19>0,60%*(250*'1'!I11),IF('1'!E11="MANUAL",60%*(IF('1'!T12>250,('1'!T12*'1'!I11),IF('1'!T12<=250,(250*'1'!I11)))))))))),IF(N19<=250,(250*'1'!I11)*60%,M19*60%)) -> 2042.28 | L21: ='1'!R14 -> PILOTO | M21: ='1'!S14 -> 2836.5 | N21: ='1'!T14 -> 250 | O21: =$O$16*M21 -> 1701.9
B22: VALOR CFR | C22: =C18+C21 -> 9013.64 | D22: =D18+D21 -> 9013.64 | E22: =SUM(C22:D22) -> 18027.28 | J22: DISTRIBUCIÓN | L22: =250*60% -> 150 | M22: =250*40% -> 100
B23: CFR CALZADO | C23: =C19+C21 -> 9013.64 | D23: =D19+D21 -> 9013.64 | E23: =SUM(C23:C23) -> 9013.64
B24: SEGURO | C24: =$E$24*C20 -> 50 | D24: =$E$24*D20 -> 50 | E24: =IF(E18<5000,50,100) -> 100
B25: VALOR CIF | C25: =C22+C24 -> 9063.64 | D25: =D22+D24 -> 9063.64 | E25: =SUM(C25:D25) -> 18127.28
B26: CIF CALZADO | C26: =C23+C24 -> 9063.64 | E26: =SUM(C26:C26) -> 9063.64
B28: TRIBUTOS APLICABLES
B31: ANTIDUMPING | C31: =C17*C30 -> 0 | E31: =SUM(C31:C31) -> 0
C33: 0 | D33: 0 | E33: TOTAL
B34: AD VALOREM | C34: =MAX(C25:C26)*C33 -> 0 | E34: =SUM(C34:C34) -> 0
B35: IGV 16% | C35: =((MAX(C25:C26))+C34)*16% -> 1450.1824 | D35: =((MAX(D25:D26))+D34)*16% -> 1450.1824 | E35: =SUM(C35:D35) -> 2900.3648
B36: IPM 2% | C36: =((MAX(C25:C26))+C34)*2% -> 181.2728 | D36: =((MAX(D25:D26))+D34)*2% -> 181.2728 | E36: =SUM(C36:D36) -> 362.5456
B37: PERCEPCIÓN 3.5% | C37: =(C25+C34+C35+C36)*3.5% -> 374.32833 | D37: =(D25+D34+D35+D36)*3.5% -> 374.32833 | E37: =SUM(C37:D37) -> 748.65666
B38: TOTAL | C38: =SUM(C34:C37) -> 2005.7835 | D38: =SUM(D34:D37) -> 2005.7835 | E38: =SUM(C38:D38) -> 4011.5671
P40: TC | Q40: 3.7
B42: COSTOS DESTINOS
C44: =+C20 -> 0.5 | D44: =+D20 -> 0.5 | E44: TOTAL
B45: ITEM | C45: =$E$45*C44 -> 680.76 | D45: =$E$45*D44 -> 680.76 | E45: =IF(M19=0,IF('1'!E11="NUEVO",'2'!M17*40%,IF('1'!E11="ANTIGUO",'2'!M18*40%,IF('1'!E11="SOCIO",40%*(250*'1'!I11),IF('1'!E11="PILOTO",40%*(250*'1'!I11),IF('2'!M19>0,40%*(250*'1'!I11),IF('1'!E11="MANUAL",40%*(IF('1'!T12>250,('1'!T12*'1'!I11),IF('1'!T12<=250,(250*'1'!I11)))))))))),IF(N19<=250,(250*'1'!I11)*40%,M19*40%)) -> 1361.52
B48: COSTO TOTAL DE IMPORTACIÓN
B50: ITEM | C50: =C11 -> Productos variados
B51: COSTO TOTAL | C51: =C18+C38+C31+'2'!C20*('1'!$J$31) -> 11700.184 | D51: =D18+D38+D31+'2'!D20*('1'!$J$31) -> 11700.184 | E51: =SUM(C51:C51) -> 11700.184
B52: CANTIDAD | C52: =+C17 -> 110182 | D52: =+D17 -> 110183
...
