Workbook

Sheet 1
E3: PRO MUNDO COMEX S.A.C.
E4: RUC: 20612452432
E7: COTIZACION N002
B8: NOMBRE: | C8: BRYAN RUIZ | E8: SERVICIO: | F8: CARGA CONSOLIDADA | I8: N° CAJAS: | J8: =+'2'!F7 -> 0
B9: APELLIDO: | E9: FECHA: | F9: =+TODAY() -> 0 | I9: PESO: | J9: 1.3704 Tn
B10: DNI/RUC: | C10: 47976981 | E10: ORIGEN: | F10: CHINA | I10: MEDIDA:
B11: TELEFONO: | C11: 929 610 511 | E11: CLIENTE: | F11: NUEVO | I11: CBM | J11: ='2'!AB7 -> 0
B13: CALCULO DE BASE IMPONIBLE | K13: MONTO | L13: MONEDA
B14: VALOR DE CARGA | K14: ='2'!AB11 -> 0 | L14: USD
B15: FLETE INTERNACIONAL + SEGURO | K15: ='2'!AB14 + '2'!AB17 -> 0 | L15: USD
B16: VALOR CIF | K16: =SUM(K14:K15) -> 0 | L16: USD
B19: CALCULO DE TRIBUTOS | J19: % | K19: MONTO | L19: MONEDA
B20: ADVALOREM | J20: =MAX('2'!C27:AA27) -> 0 | K20: ='2'!AB28 -> 0 | L20: USD | N20: Hola BRYAN RUIZ 😁 un gusto saludarte! A continuación te envío la cotización final de tu importación📋📦. 🙋‍♂️ PAGO PENDIENTE : ☑️Costo CBM: $356.4 ☑️Impuestos: $3333.59 ☑️ Total: $3689.99 Pronto le aviso nuevos avances, que tengan buen día🚢 Último día de pago:
B21: IGV | J21: 0.16 | K21: ='2'!AB29 -> 0 | L21: USD
B22: IPM | J22: 0.02 | K22: ='2'!AB30 -> 0 | L22: USD
B23: ANTIDUMPING | K23: 400
B24: SUB TOTAL | K24: =SUM(K20:K23) -> 0 | L24: USD
B26: PERCEPCIÓN | J26: 3.5% | K26: ='2'!AB31 -> 0 | L26: USD
B27: TOTAL | K27: =K24+K26 -> 0 | L27: USD
B29: RESUMEN DE COTIZACIÓN | K29: MONTO | L29: MONEDA
B30: VALOR DE CARGA (PAGO AL PROVEEDOR) | K30: =K14 -> 0 | L30: USD
B31: SERVICIO DE IMPORTACIÓN (ORIGEN -FLETE - DESTINO) | K31: =IF('2'!AF7<1, '2'!AF7*J11, '2'!AF7*J11) -> 0 | L31: USD
B32: IMPUESTOS | K32: =K27 -> 0 | L32: USD
B33: MONTO TOTAL | K33: =SUM(K30:K32) -> 0 | L33: USD
B35: SIMULACIÓN DEL PRECIO PUESTO EN PERÚ POR PIEZA
B36: # ITEM | C36: NOMBRE PRODUCTO | F36: CANTIDAD | G36: COSTO UNI. | I36: PRECIO U. | J36: TOTAL | K36: PRECIO UNIT. (SOLES)
B37: 1 | C37: CERRADURA DIGITAL | F37: ='2'!C10 -> 0 | G37: ='2'!C8 -> 0 | I37: ='2'!C46 -> 0 | J37: ='2'!C44 -> 0 | K37: ='2'!C47 -> 0
B38: 2 | C38: TORRE PARA GATOS | F38: ='2'!D10 -> 0 | G38: ='2'!D8 -> 0 | I38: ='2'!D46 -> 0 | J38: ='2'!D44 -> 0 | K38: ='2'!D47 -> 0
B39: 3 | C39: RUEDA PARA GATOS | F39: ='2'!E10 -> 0 | G39: ='2'!E8 -> 0 | I39: ='2'!E46 -> 0 | J39: ='2'!E44 -> 0 | K39: ='2'!E47 -> 0
B40: 4 | C40: GORROS DEPORTIVOS | F40: ='2'!F10 -> 0 | G40: ='2'!F8 -> 0 | I40: ='2'!F46 -> 0 | J40: ='2'!F44 -> 0 | K40: ='2'!F47 -> 0
B41: 5 | C41: CORREA PARA MASCOTA | F41: ='2'!G10 -> 0 | G41: ='2'!G8 -> 0 | I41: ='2'!G46 -> 0 | J41: ='2'!G44 -> 0 | K41: ='2'!G47 -> 0
B42: 6 | C42: PANTALON LEGGIN PARA DEPORTE | F42: ='2'!H10 -> 0 | G42: ='2'!H8 -> 0 | I42: ='2'!H46 -> 0 | J42: ='2'!H44 -> 0 | K42: ='2'!H47 -> 0
B43: 7 | C43: SHORT DEPORTIVO | F43: ='2'!I10 -> 0 | G43: ='2'!I8 -> 0 | I43: ='2'!I46 -> 0 | J43: ='2'!I44 -> 0 | K43: ='2'!I47 -> 0
B44: 8 | C44: TRICICLO PLEGABLE MULTIFUNCIONAL | F44: ='2'!J10 -> 0 | G44: ='2'!J8 -> 0 | I44: ='2'!J46 -> 0 | J44: ='2'!J44 -> 0 | K44: ='2'!J47 -> 0
B45: 9 | C45: FOCOS LED 12W | F45: ='2'!K10 -> 0 | G45: ='2'!K8 -> 0 | I45: ='2'!K46 -> 0 | J45: ='2'!K44 -> 0 | K45: ='2'!K47 -> 0
B46: 10 | C46: REBANADOR MULTIFUNCIONAL PARA PLATANOS | F46: ='2'!L10 -> 0 | G46: ='2'!L8 -> 0 | I46: ='2'!L46 -> 0 | J46: ='2'!L44 -> 0 | K46: ='2'!L47 -> 0
B47: 11 | C47: ROLLO DE ETIQUETA ADHESIVA COLOR | F47: ='2'!M10 -> 0 | G47: ='2'!M8 -> 0 | I47: ='2'!M46 -> 0 | J47: ='2'!M44 -> 0 | K47: ='2'!M47 -> 0
B48: 12 | C48: ROLLO DE ETIQUETA ADHESIVA BLANCA | F48: ='2'!N10 -> 0 | G48: ='2'!N8 -> 0 | I48: ='2'!N46 -> 0 | J48: ='2'!N44 -> 0 | K48: ='2'!N47 -> 0
B49: 13 | C49: ETIQUETA ADHESIVA TERMINCAS BLANCA | F49: ='2'!O10 -> 0 | G49: ='2'!O8 -> 0 | I49: ='2'!O46 -> 0 | J49: ='2'!O44 -> 0 | K49: ='2'!O47 -> 0
B50: 14 | C50: MAQUINA PARA PALOMITAS DE MAÍZ ZA-12 | F50: ='2'!P10 -> 0 | G50: ='2'!P8 -> 0 | I50: ='2'!P46 -> 0 | J50: ='2'!P44 -> 0 | K50: ='2'!P47 -> 0
...

Sheet 2
B3: Calculo de Tributos
B5: Nombres | C5: CERRADURA DIGITAL | D5: TORRE PARA GATOS | E5: RUEDA PARA GATOS | F5: GORROS DEPORTIVOS | G5: CORREA PARA MASCOTA | H5: PANTALON LEGGIN PARA DEPORTE | I5: SHORT DEPORTIVO | J5: TRICICLO PLEGABLE MULTIFUNCIONAL | K5: FOCOS LED 12W | L5: REBANADOR MULTIFUNCIONAL PARA PLATANOS | M5: ROLLO DE ETIQUETA ADHESIVA COLOR | N5: ROLLO DE ETIQUETA ADHESIVA BLANCA | O5: ETIQUETA ADHESIVA TERMINCAS BLANCA | P5: MAQUINA PARA PALOMITAS DE MAÍZ ZA-12 | Q5: CALENTADOR PARA PALOMITAS DE MAÍZ ZA-650 | R5: MAQUINA PARA PALOMITAS DE MAÍZ ZA-08 | S5: DISPENSADOR DE AGUA CON FILTRO PURIFICADOR | T5: MANIJA DOBLE PARA PUERTAS DE VIDRIO | U5: LAMPARA DE TECHO PARA COMEDOR | V5: LAMPARA LED DE TECHO PARA SALA | W5: LAMPARA LED PARA TECHO 3 ANILLOS | X5: LAMPARA LED DE TECHO MODERNO | Y5: ETIQUETAS ADHESIVAS TÉRMICAS HOLOGRÁFICAS 5CM | Z5: ETIQUETAS ADHESIVAS TÉRMICAS HOLOGRÁFICAS 3CM | AA5: ETIQUETAS TERMICAS IMPERMEABLES | AB5: Total
B6: Peso | C6: 0 | D6: 0 | E6: 0 | F6: 0 | G6: 0 | H6: 0 | I6: 0 | J6: 0 | K6: 0 | L6: 0 | M6: 0 | N6: 0 | O6: 0 | P6: 0 | Q6: 0 | R6: 0 | S6: 0 | T6: 0 | U6: 0 | V6: 0 | W6: 0 | X6: 0 | Y6: 0 | Z6: 0 | AA6: 0 | AB6: 1.37 | AE6: Tipo Cliente | AF6: Tarifa
B7: Valor CBM | C7: 0 | D7: 0 | E7: 0 | F7: 0 | G7: 0 | H7: 0 | I7: 0 | J7: 0 | K7: 0 | L7: 0 | M7: 0 | N7: 0 | O7: 0 | P7: 0 | Q7: 0 | R7: 0 | S7: 0 | T7: 0 | U7: 0 | V7: 0 | W7: 0 | X7: 0 | Y7: 0 | Z7: 0 | AA7: 0 | AB7: 2 | AE7: NUEVO | AF7: 300
B8: Valor Unitario | C8: 16.392308 | D8: 31.333333 | E8: 26.18 | F8: 1.59 | G8: 0.88 | H8: 4.24625 | I8: 3.3841667 | J8: 39.9 | K8: 0.9 | L8: 110 | M8: 3.2 | N8: 2.125 | O8: 3.4 | P8: 380 | Q8: 295 | R8: 125 | S8: 8.6 | T8: 1.885 | U8: 7.1 | V8: 4.4 | W8: 5.8 | X8: 10 | Y8: 4.19 | Z8: 1.9025 | AA8: 0.62333333
B9: Valoracion | C9: 0 | D9: 0 | E9: 0 | F9: 0 | G9: 0 | H9: 0 | I9: 0 | J9: 0 | K9: 0 | L9: 0 | M9: 0 | N9: 0 | O9: 0 | P9: 0 | Q9: 0 | R9: 0 | S9: 0 | T9: 0 | U9: 0 | V9: 0 | W9: 0 | X9: 0 | Y9: 0 | Z9: 0 | AA9: 0
B10: Cantidad | C10: 65 | D10: 6 | E10: 1 | F10: 200 | G10: 200 | H10: 400 | I10: 240 | J10: 30 | K10: 300 | L10: 6 | M10: 60 | N10: 120 | O10: 90 | P10: 4 | Q10: 2 | R10: 6 | S10: 36 | T10: 700 | U10: 4 | V10: 10 | W10: 20 | X10: 9 | Y10: 80 | Z10: 320 | AA10: 240 | AB10: =SUM(C10:AA10) -> 0
B11: Valor FOB | C11: =C8*C10 -> 0 | D11: =D8*D10 -> 0 | E11: =E8*E10 -> 0 | F11: =F8*F10 -> 0 | G11: =G8*G10 -> 0 | H11: =H8*H10 -> 0 | I11: =I8*I10 -> 0 | J11: =J8*J10 -> 0 | ... AA11: =AA8*AA10 -> 0 | AB11: =SUM(C11:AA11) -> 0
B12: Valor FOB Valoracion | C12: =C10*C9 -> 0 | D12: =D10*D9 -> 0 | E12: =E10*E9 -> 0 | F12: =F10*F9 -> 0 | G12: =G10*G9 -> 0 | H12: =H10*H9 -> 0 | I12: =I10*I9 -> 0 | J12: =J10*J9 -> 0 | ... AA12: =AA10*AA9 -> 0 | AB12: =SUM(C12:AA12) -> 0
B13: Distribucion % | C13: =C11/AB11 -> 0 | D13: =D11/AB11 -> 0 | E13: =E11/AB11 -> 0 | F13: =F11/AB11 -> 0 | G13: =G11/AB11 -> 0 | H13: =H11/AB11 -> 0 | I13: =I11/AB11 -> 0 | J13: =J11/AB11 -> 0 | K13: =K11/AB11 -> 0 | L13: =L11/AB11 -> 0 | M13: =M11/AB11 -> 0 | N13: =N11/AB11 -> 0 | O13: =O11/AB11 -> 0 | P13: =P11/AB11 -> 0 | Q13: =Q11/AB11 -> 0 | R13: =R11/AB11 -> 0 | S13: =S11/AB11 -> 0 | T13: =T11/AB11 -> 0 | U13: =U11/AB11 -> 0 | V13: =V11/AB11 -> 0 | W13: =W11/AB11 -> 0 | X13: =X11/AB11 -> 0 | Y13: =Y11/AB11 -> 0 | Z13: =Z11/AB11 -> 0 | AA13: =AA11/AB11 -> 0
B14: Flete | C14: =ROUNDUP(AB14*C13,2) -> 0 | D14: =ROUNDUP(AB14*D13,2) -> 0 | E14: =ROUNDUP(AB14*E13,2) -> 0 | F14: =ROUNDUP(AB14*F13,2) -> 0 | G14: =ROUNDUP(AB14*G13,2) -> 0 | H14: =ROUNDUP(AB14*H13,2) -> 0 | I14: =ROUNDUP(AB14*I13,2) -> 0 | J14: =ROUNDUP(AB14*J13,2) -> 0 | K14: =ROUNDUP(AB14*K13,2) -> 0 | L14: =ROUNDUP(AB14*L13,2) -> 0 | M14: =ROUNDUP(AB14*M13,2) -> 0 | N14: =ROUNDUP(AB14*N13,2) -> 0 | O14: =ROUNDUP(AB14*O13,2) -> 0 | P14: =ROUNDUP(AB14*P13,2) -> 0 | Q14: =ROUNDUP(AB14*Q13,2) -> 0 | R14: =ROUNDUP(AB14*R13,2) -> 0 | S14: =ROUNDUP(AB14*S13,2) -> 0 | T14: =ROUNDUP(AB14*T13,2) -> 0 | U14: =ROUNDUP(AB14*U13,2) -> 0 | V14: =ROUNDUP(AB14*V13,2) -> 0 | W14: =ROUNDUP(AB14*W13,2) -> 0 | X14: =ROUNDUP(AB14*X13,2) -> 0 | Y14: =ROUNDUP(AB14*Y13,2) -> 0 | Z14: =ROUNDUP(AB14*Z13,2) -> 0 | AA14: =ROUNDUP(AB14*AA13,2) -> 0 | AB14: =IF(AB7<1, ROUNDUP(AF7*0.6, 0), ROUNDUP(AF7*0.6*AB7, 0)) -> 0
B15: Valor CFR | C15: =ROUNDUP(C11+C14,2) -> 0 | D15: =ROUNDUP(D11+D14,2) -> 0 | E15: =ROUNDUP(E11+E14,2) -> 0 | F15: =ROUNDUP(F11+F14,2) -> 0 | G15: =ROUNDUP(G11+G14,2) -> 0 | H15: =ROUNDUP(H11+H14,2) -> 0 | I15: =ROUNDUP(I11+I14,2) -> 0 | J15: =ROUNDUP(J11+J14,2) -> 0 | ... AA15: =ROUNDUP(AA11+AA14,2) -> 0 | AB15: =SUM(C15:AA15) -> 0
B16: CFR Valorizado | C16: =ROUNDUP(C12+C14,2) -> 0 | D16: =ROUNDUP(D12+D14,2) -> 0 | E16: =ROUNDUP(E12+E14,2) -> 0 | F16: =ROUNDUP(F12+F14,2) -> 0 | G16: =ROUNDUP(G12+G14,2) -> 0 | H16: =ROUNDUP(H12+H14,2) -> 0 | I16: =ROUNDUP(I12+I14,2) -> 0 | J16: =ROUNDUP(J12+J14,2) -> 0 | ... AA16: =ROUNDUP(AA12+AA14,2) -> 0 | AB16: =SUM(C16:AA16) -> 0
B17: Seguro | C17: =IF(AB15>5000,ROUND(100*C13,2),ROUND(50*C13,2)) -> 0 | D17: =IF(AB15>5000,ROUND(100*D13,2),ROUND(50*D13,2)) -> 0 | E17: =IF(AB15>5000,ROUND(100*E13,2),ROUND(50*E13,2)) -> 0 | F17: =IF(AB15>5000,ROUND(100*F13,2),ROUND(50*F13,2)) -> 0 | G17: =IF(AB15>5000,ROUND(100*G13,2),ROUND(50*G13,2)) -> 0 | H17: =IF(AB15>5000,ROUND(100*H13,2),ROUND(50*H13,2)) -> 0 | I17: =IF(AB15>5000,ROUND(100*I13,2),ROUND(50*I13,2)) -> 0 | J17: =IF(AB15>5000,ROUND(100*J13,2),ROUND(50*J13,2)) -> 0 | K17: =IF(AB15>5000,ROUND(100*K13,2),ROUND(50*K13,2)) -> 0 | L17: =IF(AB15>5000,ROUND(100*L13,2),ROUND(50*L13,2)) -> 0 | M17: =IF(AB15>5000,ROUND(100*M13,2),ROUND(50*M13,2)) -> 0 | N17: =IF(AB15>5000,ROUND(100*N13,2),ROUND(50*N13,2)) -> 0 | O17: =IF(AB15>5000,ROUND(100*O13,2),ROUND(50*O13,2)) -> 0 | P17: =IF(AB15>5000,ROUND(100*P13,2),ROUND(50*P13,2)) -> 0 | Q17: =IF(AB15>5000,ROUND(100*Q13,2),ROUND(50*Q13,2)) -> 0 | R17: =IF(AB15>5000,ROUND(100*R13,2),ROUND(50*R13,2)) -> 0 | S17: =IF(AB15>5000,ROUND(100*S13,2),ROUND(50*S13,2)) -> 0 | T17: =IF(AB15>5000,ROUND(100*T13,2),ROUND(50*T13,2)) -> 0 | U17: =IF(AB15>5000,ROUND(100*U13,2),ROUND(50*U13,2)) -> 0 | V17: =IF(AB15>5000,ROUND(100*V13,2),ROUND(50*V13,2)) -> 0 | W17: =IF(AB15>5000,ROUND(100*W13,2),ROUND(50*W13,2)) -> 0 | X17: =IF(AB15>5000,ROUND(100*X13,2),ROUND(50*X13,2)) -> 0 | Y17: =IF(AB15>5000,ROUND(100*Y13,2),ROUND(50*Y13,2)) -> 0 | Z17: =IF(AB15>5000,ROUND(100*Z13,2),ROUND(50*Z13,2)) -> 0 | AA17: =IF(AB15>5000,ROUND(100*AA13,2),ROUND(50*AA13,2)) -> 0 | AB17: =SUM(C17:AA17) -> 0
B18: Valor CIF | C18: =ROUNDUP(C15+C17,2) -> 0 | D18: =ROUNDUP(D15+D17,2) -> 0 | E18: =ROUNDUP(E15+E17,2) -> 0 | F18: =ROUNDUP(F15+F17,2) -> 0 | G18: =ROUNDUP(G15+G17,2) -> 0 | H18: =ROUNDUP(H15+H17,2) -> 0 | I18: =ROUNDUP(I15+I17,2) -> 0 | J18: =ROUNDUP(J15+J17,2) -> 0 | ... AA18: =ROUNDUP(AA15+AA17,2) -> 0 | AB18: =SUM(C18:AA18) -> 0
B19: CIF Valorizado | C19: =ROUNDUP(C16+C17,2) -> 0 | D19: =ROUNDUP(D16+D17,2) -> 0 | E19: =ROUNDUP(E16+E17,2) -> 0 | F19: =ROUNDUP(F16+F17,2) -> 0 | G19: =ROUNDUP(G16+G17,2) -> 0 | H19: =ROUNDUP(H16+H17,2) -> 0 | I19: =ROUNDUP(I16+I17,2) -> 0 | J19: =ROUNDUP(J16+J17,2) -> 0 | ... AA19: =ROUNDUP(AA16+AA17,2) -> 0 | AB19: =SUM(C19:AA19) -> 0
B23: Tributos Aplicables
B26: ANTIDUMPING | C26: 0 | D26: 0 | E26: 0 | F26: 400 | G26: 0 | H26: 0 | I26: 0 | J26: 0 | K26: 0 | L26: 0 | M26: 0 | N26: 0 | O26: 0 | P26: 0 | Q26: 0 | R26: 0 | S26: 0 | T26: 0 | U26: 0 | V26: 0 | W26: 0 | X26: 0 | Y26: 0 | Z26: 0 | AA26: 0 | AB26: =SUM(C26:AA26) -> 0
C27: 0 | D27: 0 | E27: 0 | F27: 0 | G27: 0 | H27: 0.11 | I27: 0.11 | J27: 0 | K27: 0 | L27: 0 | M27: 0 | N27: 0 | O27: 0 | P27: 0 | Q27: 0 | R27: 0 | S27: 0 | T27: 0 | U27: 0 | V27: 0 | W27: 0 | X27: 0 | Y27: 0 | Z27: 0 | AA27: 0 | AB27: =SUM(C27:AA27) -> 0
B28: AD VALOREM | C28: =MAX(C19,C18)*C27 -> 0 | D28: =MAX(D19,D18)*D27 -> 0 | E28: =MAX(E19,E18)*E27 -> 0 | F28: =MAX(F19,F18)*F27 -> 0 | G28: =MAX(G19,G18)*G27 -> 0 | H28: =MAX(H19,H18)*H27 -> 0 | I28: =MAX(I19,I18)*I27 -> 0 | J28: =MAX(J19,J18)*J27 -> 0 | ... AA28: =MAX(AA19,AA18)*AA27 -> 0 | AB28: =SUM(C28:AA28) -> 0
B29: IGV | C29: =0.16*(MAX(C19,C18)+C28) -> 0 | D29: =0.16*(MAX(D19,D18)+D28) -> 0 | E29: =0.16*(MAX(E19,E18)+E28) -> 0 | F29: =0.16*(MAX(F19,F18)+F28) -> 0 | G29: =0.16*(MAX(G19,G18)+G28) -> 0 | H29: =0.16*(MAX(H19,H18)+H28) -> 0 | I29: =0.16*(MAX(I19,I18)+I28) -> 0 | J29: =0.16*(MAX(J19,J18)+J28) -> 0 | ... AA29: =0.16*(MAX(AA19,AA18)+AA28) -> 0 | AB29: =SUM(C29:AA29) -> 0
B30: IPM | C30: =0.02*(MAX(C19,C18)+C28) -> 0 | D30: =0.02*(MAX(D19,D18)+D28) -> 0 | E30: =0.02*(MAX(E19,E18)+E28) -> 0 | F30: =0.02*(MAX(F19,F18)+F28) -> 0 | G30: =0.02*(MAX(G19,G18)+G28) -> 0 | H30: =0.02*(MAX(H19,H18)+H28) -> 0 | I30: =0.02*(MAX(I19,I18)+I28) -> 0 | J30: =0.02*(MAX(J19,J18)+J28) -> 0 | ... AA30: =0.02*(MAX(AA19,AA18)+AA28) -> 0 | AB30: =SUM(C30:AA30) -> 0
B31: PERCEPCION | C31: =0.035*(MAX(C18,C19) +C28+C29+C30) -> 0 | D31: =0.035*(MAX(D18,D19) +D28+D29+D30) -> 0 | E31: =0.035*(MAX(E18,E19) +E28+E29+E30) -> 0 | F31: =0.035*(MAX(F18,F19) +F28+F29+F30) -> 0 | G31: =0.035*(MAX(G18,G19) +G28+G29+G30) -> 0 | H31: =0.035*(MAX(H18,H19) +H28+H29+H30) -> 0 | I31: =0.035*(MAX(I18,I19) +I28+I29+I30) -> 0 | J31: =0.035*(MAX(J18,J19) +J28+J29+J30) -> 0 | ... AA31: =0.035*(MAX(AA18,AA19) +AA28+AA29+AA30) -> 0 | AB31: =SUM(C31:AA31) -> 0
B32: TOTAL | C32: =SUM(C28:C31) -> 0 | D32: =SUM(D28:D31) -> 0 | E32: =SUM(E28:E31) -> 0 | F32: =SUM(F28:F31) -> 0 | G32: =SUM(G28:G31) -> 0 | H32: =SUM(H28:H31) -> 0 | I32: =SUM(I28:I31) -> 0 | J32: =SUM(J28:J31) -> 0 | ... AB32: =SUM(AB28:AB31) -> 0
B37: Costos Destinos
B40: ITEM | C40: =C13*AB40 -> 0 | D40: =D13*AB40 -> 0 | E40: =E13*AB40 -> 0 | F40: =F13*AB40 -> 0 | G40: =G13*AB40 -> 0 | H40: =H13*AB40 -> 0 | I40: =I13*AB40 -> 0 | J40: =J13*AB40 -> 0 | K40: =K13*AB40 -> 0 | L40: =L13*AB40 -> 0 | M40: =M13*AB40 -> 0 | N40: =N13*AB40 -> 0 | O40: =O13*AB40 -> 0 | P40: =P13*AB40 -> 0 | Q40: =Q13*AB40 -> 0 | R40: =R13*AB40 -> 0 | S40: =S13*AB40 -> 0 | T40: =T13*AB40 -> 0 | U40: =U13*AB40 -> 0 | V40: =V13*AB40 -> 0 | W40: =W13*AB40 -> 0 | X40: =X13*AB40 -> 0 | Y40: =Y13*AB40 -> 0 | Z40: =Z13*AB40 -> 0 | AA40: =AA13*AB40 -> 0 | AB40: =IF(AB7<1, ROUNDUP(AF7*0.4, 0), ROUNDUP(AF7*0.4*AB7, 0)) -> 0
B43: ITEM | C43: CERRADURA DIGITAL | D43: TORRE PARA GATOS | E43: RUEDA PARA GATOS | F43: GORROS DEPORTIVOS | G43: CORREA PARA MASCOTA | H43: PANTALON LEGGIN PARA DEPORTE | I43: SHORT DEPORTIVO | J43: TRICICLO PLEGABLE MULTIFUNCIONAL | K43: FOCOS LED 12W | L43: REBANADOR MULTIFUNCIONAL PARA PLATANOS | M43: ROLLO DE ETIQUETA ADHESIVA COLOR | N43: ROLLO DE ETIQUETA ADHESIVA BLANCA | O43: ETIQUETA ADHESIVA TERMINCAS BLANCA | P43: MAQUINA PARA PALOMITAS DE MAÍZ ZA-12 | Q43: CALENTADOR PARA PALOMITAS DE MAÍZ ZA-650 | R43: MAQUINA PARA PALOMITAS DE MAÍZ ZA-08 | S43: DISPENSADOR DE AGUA CON FILTRO PURIFICADOR | T43: MANIJA DOBLE PARA PUERTAS DE VIDRIO | U43: LAMPARA DE TECHO PARA COMEDOR | V43: LAMPARA LED DE TECHO PARA SALA | W43: LAMPARA LED PARA TECHO 3 ANILLOS | X43: LAMPARA LED DE TECHO MODERNO | Y43: ETIQUETAS ADHESIVAS TÉRMICAS HOLOGRÁFICAS 5CM | Z43: ETIQUETAS ADHESIVAS TÉRMICAS HOLOGRÁFICAS 3CM | AA43: ETIQUETAS TERMICAS IMPERMEABLES | AB43: Total
B44: COSTO TOTAL | C44: =SUM(C15,C40,C32,(C26*C10)) -> 0 | D44: =SUM(D15,D40,D32,(D26*D10)) -> 0 | E44: =SUM(E15,E40,E32,(E26*E10)) -> 0 | F44: =SUM(F15,F40,F32,(F26*F10)) -> 0 | G44: =SUM(G15,G40,G32,(G26*G10)) -> 0 | H44: =SUM(H15,H40,H32,(H26*H10)) -> 0 | I44: =SUM(I15,I40,I32,(I26*I10)) -> 0 | J44: =SUM(J15,J40,J32,(J26*J10)) -> 0 | ... AA44: =SUM(AA15,AA40,AA32,(AA26*AA10)) -> 0 | AB44: =SUM(C44:AA44) -> 0
B45: CANTIDAD | C45: 65 | D45: 6 | E45: 1 | F45: 200 | G45: 200 | H45: 400 | I45: 240 | J45: 30 | K45: 300 | L45: 6 | M45: 60 | N45: 120 | O45: 90 | P45: 4 | Q45: 2 | R45: 6 | S45: 36 | T45: 700 | U45: 4 | V45: 10 | W45: 20 | X45: 9 | Y45: 80 | Z45: 320 | AA45: 240
B46: COSTO UNITARIO | C46: =ROUND(SUM(C44/C45),2) -> 0 | D46: =ROUND(SUM(D44/D45),2) -> 0 | E46: =ROUND(SUM(E44/E45),2) -> 0 | F46: =ROUND(SUM(F44/F45),2) -> 0 | G46: =ROUND(SUM(G44/G45),2) -> 0 | H46: =ROUND(SUM(H44/H45),2) -> 0 | I46: =ROUND(SUM(I44/I45),2) -> 0 | J46: =ROUND(SUM(J44/J45),2) -> 0 | ... AA46: =ROUND(SUM(AA44/AA45),2) -> 0
B47: COSTO SOLES | C47: =ROUND(C46*3.7,2) -> 0 | D47: =ROUND(D46*3.7,2) -> 0 | E47: =ROUND(E46*3.7,2) -> 0 | F47: =ROUND(F46*3.7,2) -> 0 | G47: =ROUND(G46*3.7,2) -> 0 | H47: =ROUND(H46*3.7,2) -> 0 | I47: =ROUND(I46*3.7,2) -> 0 | J47: =ROUND(J46*3.7,2) -> 0 | ... AA47: =ROUND(AA46*3.7,2) -> 0
